Workbook

Sheet Revision_History
A2: Revision history
B5: Version | C5: Date | D5: Sheet | E5: Comment | F5: Written by | G5: Checked by | H5: Approved by
B6: 1.0 | C6: 42761 | D6: All | E6: Preparation for V5.4 regression test. | F6: RVC/Thuy Tran GCS/Muoi Nguyen | G6: RVC/Thuy Tran | H6: RVC/Hieu Nguyen
B7: 1.1 | C7: 42788 | D7: All | E7: Test result of V5.4 RUN1. | F7: GCS/Muoi Nguyen | G7: RVC/Thuy Tran | H7: RVC/Hieu Nguyen
B8: 1.2 | C8: 42793 | D8: All | E8: Test preparation of V5.4 RUN2. | F8: RVC/Thuy Tran | G8: RVC/Thuy Tran | H8: RVC/Hieu Nguyen
B9: 1.3 | C9: 42811 | D9: All | E9: Test result of V5.4 RUN2. | F9: GCS/Muoi Nguyen | G9: RVC/Thuy Tran | H9: RVC/Hieu Nguyen

Sheet Summary
A2: V5.4 Regression Test | O2: Select the current RUN: | P2: 1 | R2: 1 | AM2: 2 | BH2: 3 | CC2: 4 | CX2: 5
E4: Result on 5.2.0.019, SSP_1.1.0-alpha | R4: e2studio_v5.4.0.001-Part1 | AM4: e2studio_v5.4.0.005 | BH4: TBD | CC4: TBD | CX4: TBD
C5: Component/Plug-in | E5: 5.3 test cases | G5: Total test cases | J5: Executed test cases | M5: Skipped test cases | N5: Jubula limitation | O5: PIC (RVC/GCS) | P5: Remark | Q5: Diff Level (by GCS in V5.3) | R5: Total test cases | U5: % | V5: Executed test cases | AE5: Skipped test cases | AI5: PIC (RVC/GCS) | AJ5: Note for FAIL | AK5: Remark | AM5: Total test cases | AP5: % | AQ5: Executed test cases | AZ5: Skipped test cases | BD5: PIC (RVC/GCS) | BE5: Note for FAIL | BF5: Remark | BH5: Total test cases | BK5: % | BL5: Executed test cases | BU5: Skipped test cases | BY5: PIC (RVC/GCS) | BZ5: Note for FAIL | CA5: Remark | CC5: Total test cases | CF5: % | CG5: Executed test cases | CP5: Skipped test cases | CT5: PIC (RVC/GCS) | CU5: Note for FAIL | CV5: Remark | CX5: Total test cases | DA5: % | DB5: Executed test cases | DK5: Skipped test cases | DO5: PIC (RVC/GCS) | DP5: Note for FAIL | DQ5: Remark
E6: New | F6: Existing | G6: Sum | H6: Auto | I6: Manual | J6: Sum | K6: PASS | L6: FALSE | R6: Sum | S6: Auto | T6: Manual | V6: Sum | Y6: Auto | AB6: Manual | AE6: Sum | AF6: Auto | AG6: Manual | AH6: Reason of skipping | AM6: Sum | AN6: Auto | AO6: Manual | AQ6: Sum | AT6: Auto | AW6: Manual | AZ6: Sum | BA6: Auto | BB6: Manual | BC6: Reason of skipping | BH6: Sum | BI6: Auto | BJ6: Manual | BL6: Sum | BO6: Auto | BR6: Manual | BU6: Sum | BV6: Auto | BW6: Manual | BX6: Reason of skipping | CC6: Sum | CD6: Auto | CE6: Manual | CG6: Sum | CJ6: Auto | CM6: Manual | CP6: Sum | CQ6: Auto | CR6: Manual | CS6: Reason of skipping | CX6: Sum | CY6: Auto | CZ6: Manual | DB6: Sum | DE6: Auto | DH6: Manual | DK6: Sum | DL6: Auto | DM6: Manual | DN6: Reason of skipping
V7: Total | W7: Pass | X7: Fail | Y7: Total | Z7: Pass | AA7: Fail | AB7: Total | AC7: Pass | AD7: Fail | AQ7: Total | AR7: Pass | AS7: Fail | AT7: Total | AU7: Pass | AV7: Fail | AW7: Total | AX7: Pass | AY7: Fail | BL7: Total | BM7: Pass | BN7: Fail | BO7: Total | BP7: Pass | BQ7: Fail | BR7: Total | BS7: Pass | BT7: Fail | CG7: Total | CH7: Pass | CI7: Fail | CJ7: Total | CK7: Pass | CL7: Fail | CM7: Total | CN7: Pass | CO7: Fail | DB7: Total | DC7: Pass | DD7: Fail | DE7: Total | DF7: Pass | DG7: Fail | DH7: Total | DI7: Pass | DJ7: Fail
C8: # | D8: Number of test cases | E8: =SUM(E9:E21) -> 0 | F8: =SUM(F9:F21) -> 388 | G8: =SUM(G9:G21) -> 388 | H8: =SUM(H9:H21) -> 329 | I8: =SUM(I9:I21) -> 59 | J8: =SUM(J9:J21) -> 0 | K8: =SUM(K9:K21) -> 0 | L8: =SUM(L9:L21) -> 0 | ... N8: =SUM(N9:N21) -> 0 | R8: =SUM(R9:R21) -> 388 | S8: =SUM(S9:S21) -> 329 | T8: =SUM(T9:T21) -> 59 | U8: =IFERROR(V8/R8,"-") -> 1 | V8: =SUM(V9:V21) -> 388 | W8: =SUM(W9:W21) -> 383 | X8: =SUM(X9:X21) -> 5 | Y8: =SUM(Y9:Y21) -> 329 | Z8: =SUM(Z9:Z21) -> 325 | AA8: =SUM(AA9:AA21) -> 4 | AB8: =SUM(AB9:AB21) -> 59 | AC8: =SUM(AC9:AC21) -> 58 | ... AG8: =SUM(AG9:AG21) -> 0 | AM8: =SUM(AM9:AM21) -> 388 | AN8: =SUM(AN9:AN21) -> 329 | AO8: =SUM(AO9:AO21) -> 59 | AP8: =IFERROR(AQ8/AM8,"-") -> 1 | AQ8: =SUM(AQ9:AQ21) -> 388 | AR8: =SUM(AR9:AR21) -> 384 | AS8: =SUM(AS9:AS21) -> 4 | AT8: =SUM(AT9:AT21) -> 329 | AU8: =SUM(AU9:AU21) -> 325 | AV8: =SUM(AV9:AV21) -> 4 | AW8: =SUM(AW9:AW21) -> 59 | AX8: =SUM(AX9:AX21) -> 59 | ... BB8: =SUM(BB9:BB21) -> 0 | BH8: =SUM(BH9:BH21) -> 0 | BI8: =SUM(BI9:BI21) -> 0 | BJ8: =SUM(BJ9:BJ21) -> 0 | BK8: =IFERROR(BL8/BH8,"-") -> - | BL8: =SUM(BL9:BL21) -> 0 | BM8: =SUM(BM9:BM21) -> 0 | BN8: =SUM(BN9:BN21) -> 0 | BO8: =SUM(BO9:BO21) -> 0 | BP8: =SUM(BP9:BP21) -> 0 | BQ8: =SUM(BQ9:BQ21) -> 0 | BR8: =SUM(BR9:BR21) -> 0 | BS8: =SUM(BS9:BS21) -> 0 | ... BW8: =SUM(BW9:BW21) -> 0 | CC8: =SUM(CC9:CC21) -> 0 | CD8: =SUM(CD9:CD21) -> 0 | CE8: =SUM(CE9:CE21) -> 0 | CF8: =IFERROR(CG8/CC8,"-") -> - | CG8: =SUM(CG9:CG21) -> 0 | CH8: =SUM(CH9:CH21) -> 0 | CI8: =SUM(CI9:CI21) -> 0 | CJ8: =SUM(CJ9:CJ21) -> 0 | CK8: =SUM(CK9:CK21) -> 0 | CL8: =SUM(CL9:CL21) -> 0 | CM8: =SUM(CM9:CM21) -> 0 | CN8: =SUM(CN9:CN21) -> 0 | ... CR8: =SUM(CR9:CR21) -> 0 | CX8: =SUM(CX9:CX21) -> 0 | CY8: =SUM(CY9:CY21) -> 0 | CZ8: =SUM(CZ9:CZ21) -> 0 | DA8: =IFERROR(DB8/CX8,"-") -> - | DB8: =SUM(DB9:DB21) -> 0 | DC8: =SUM(DC9:DC21) -> 0 | DD8: =SUM(DD9:DD21) -> 0 | DE8: =SUM(DE9:DE21) -> 0 | DF8: =SUM(DF9:DF21) -> 0 | DG8: =SUM(DG9:DG21) -> 0 | DH8: =SUM(DH9:DH21) -> 0 | DI8: =SUM(DI9:DI21) -> 0 | ... DM8: =SUM(DM9:DM21) -> 0
C9: Bu_#1 | D9: Builder_Common | E9: =INDIRECT("'"&D9&"'!"&"C6") -> 0 | F9: =G9-E9 -> 157 | G9: =INDIRECT("'"&D9&"'!"&"C1") -> 157 | H9: =INDIRECT("'"&D9&"'!"&"C2") -> 139 | I9: =G9-H9 -> 18 | J9: =SUM(K9:L9) -> 0 | K9: =INDIRECT("'"&D9&"'!"&"L5") -> 0 | L9: =INDIRECT("'"&D9&"'!"&"L6") -> 0 | M9: =INDIRECT("'"&D9&"'!"&"L7") -> 0 | N9: =INDIRECT("'"&D9&"'!"&"E3") -> 0 | O9: =(IF(INDIRECT("'"&D9&"'!"&"L3")=0,"-","-RVC="&INDIRECT("'"&D9&"'!"&"L3")&"-"))&IF(INDIRECT("'"&D9&"'!"&"L4")=0,"-","-GCS="&INDIRECT("'"&D9&"'!"&"L4")&"-") -> -- | Q9: =INDIRECT(CONCATENATE("'",$D9,"'!$AN$12")) -> N | R9: =SUM(S9:T9) -> 157 | S9: 139 | T9: 18 | U9: =IFERROR(V9/R9,"-") -> 1 | V9: =INDIRECT("'"&D9&"'!"&"P3") -> 157 | W9: =INDIRECT("'"&D9&"'!"&"P4") -> 152 | X9: =INDIRECT("'"&D9&"'!"&"P5") -> 5 | Y9: =INDIRECT("'"&D9&"'!"&"Q3") -> 139 | Z9: =INDIRECT("'"&D9&"'!"&"Q4") -> 135 | AA9: =INDIRECT("'"&D9&"'!"&"Q5") -> 4 | AB9: =INDIRECT("'"&D9&"'!"&"R3") -> 18 | AC9: =INDIRECT("'"&D9&"'!"&"R4") -> 17 | AD9: =INDIRECT("'"&D9&"'!"&"R5") -> 1 | AE9: =INDIRECT("'"&D9&"'!"&"P10") -> 0 | AF9: =INDIRECT("'"&D9&"'!"&"Q10") -> 0 | AG9: =INDIRECT("'"&D9&"'!"&"R10") -> 0 | AI9: =(IF(INDIRECT("'"&D9&"'!"&"P1")=0,"-","-RVC="&INDIRECT("'"&D9&"'!"&"P1")))&IF(INDIRECT("'"&D9&"'!"&"R1")=0,"-","-GCS="&INDIRECT("'"&D9&"'!"&"R1")) -> --GCS=157 | AJ9: 5 fail (Known) due: IDE-9544 | AK9: GCS | AL9: =INDIRECT(CONCATENATE("'",$D9,"'!$AR$3")) -> E | AM9: =SUM(AN9:AO9) -> 157 | AN9: 139 | AO9: 18 | AP9: =IFERROR(AQ9/AM9,"-") -> 1 | AQ9: =INDIRECT("'"&D9&"'!"&"T3") -> 157 | AR9: =INDIRECT("'"&D9&"'!"&"T4") -> 153 | AS9: =INDIRECT("'"&D9&"'!"&"T5") -> 4 | AT9: =INDIRECT("'"&D9&"'!"&"U3") -> 139 | AU9: =INDIRECT("'"&D9&"'!"&"U4") -> 135 | AV9: =INDIRECT("'"&D9&"'!"&"U5") -> 4 | AW9: =INDIRECT("'"&D9&"'!"&"V3") -> 18 | AX9: =INDIRECT("'"&D9&"'!"&"V4") -> 18 | AY9: =INDIRECT("'"&D9&"'!"&"V5") -> 0 | AZ9: =INDIRECT("'"&D9&"'!"&"T10") -> 0 | BA9: =INDIRECT("'"&D9&"'!"&"U10") -> 0 | BB9: =INDIRECT("'"&D9&"'!"&"V10") -> 0 | BD9: =(IF(INDIRECT("'"&D9&"'!"&"T1")=0,"-","-RVC="&INDIRECT("'"&D9&"'!"&"T1")))&IF(INDIRECT("'"&D9&"'!"&"V1")=0,"-","-GCS="&INDIRECT("'"&D9&"'!"&"V1")) -> --GCS=157 | BE9: IDE-9544 | BF9: GCS | BG9: =INDIRECT(CONCATENATE("'",$D9,"'!$AR$4")) -> E | BH9: =SUM(BI9:BJ9) -> 0 | BK9: =IFERROR(BL9/BH9,"-") -> - | BL9: =INDIRECT("'"&D9&"'!"&"X3") -> 0 | BM9: =INDIRECT("'"&D9&"'!"&"X4") -> 0 | BN9: =INDIRECT("'"&D9&"'!"&"X5") -> 0 | BO9: =INDIRECT("'"&D9&"'!"&"Y3") -> 0 | BP9: =INDIRECT("'"&D9&"'!"&"Y4") -> 0 | BQ9: =INDIRECT("'"&D9&"'!"&"Y5") -> 0 | BR9: =INDIRECT("'"&D9&"'!"&"Z3") -> 0 | BS9: =INDIRECT("'"&D9&"'!"&"Z4") -> 0 | BT9: =INDIRECT("'"&D9&"'!"&"Z5") -> 0 | BU9: =INDIRECT("'"&D9&"'!"&"X10") -> 0 | BV9: =INDIRECT("'"&D9&"'!"&"Y10") -> 0 | BW9: =INDIRECT("'"&D9&"'!"&"Z10") -> 0 | BY9: =(IF(INDIRECT("'"&D9&"'!"&"V1")=0,"-","-RVC="&INDIRECT("'"&D9&"'!"&"V1")))&IF(INDIRECT("'"&D9&"'!"&"X1")=0,"-","-GCS="&INDIRECT("'"&D9&"'!"&"X1")) -> -RVC=157- | CB9: =INDIRECT(CONCATENATE("'",$D9,"'!$AR$5")) -> NOT-YET | CC9: =SUM(CD9:CE9) -> 0 | CF9: =IFERROR(CG9/CC9,"-") -> - | CG9: =INDIRECT("'"&D9&"'!"&"AB3") -> 0 | CH9: =INDIRECT("'"&D9&"'!"&"AB4") -> 0 | CI9: =INDIRECT("'"&D9&"'!"&"AB5") -> 0 | CJ9: =INDIRECT("'"&D9&"'!"&"AC3") -> 0 | CK9: =INDIRECT("'"&D9&"'!"&"AC4") -> 0 | CL9: =INDIRECT("'"&D9&"'!"&"AC5") -> 0 | CM9: =INDIRECT("'"&D9&"'!"&"AD3") -> 0 | CN9: =INDIRECT("'"&D9&"'!"&"AD4") -> 0 | CO9: =INDIRECT("'"&D9&"'!"&"AD5") -> 0 | CP9: =INDIRECT("'"&D9&"'!"&"AB10") -> 0 | CQ9: =INDIRECT("'"&D9&"'!"&"AC10") -> 0 | CR9: =INDIRECT("'"&D9&"'!"&"AD10") -> 0 | CT9: =(IF(INDIRECT("'"&D9&"'!"&"Z1")=0,"-","-RVC="&INDIRECT("'"&D9&"'!"&"Z1")))&IF(INDIRECT("'"&D9&"'!"&"AB1")=0,"-","-GCS="&INDIRECT("'"&D9&"'!"&"AB1")) -> -- | CX9: =SUM(CY9:CZ9) -> 0 | DA9: =IFERROR(DB9/CX9,"-") -> - | DB9: =INDIRECT("'"&D9&"'!"&"AF3") -> 0 | DC9: =INDIRECT("'"&D9&"'!"&"AF4") -> 0 | DD9: =INDIRECT("'"&D9&"'!"&"AF5") -> 0 | DE9: =INDIRECT("'"&D9&"'!"&"AG3") -> 0 | DF9: =INDIRECT("'"&D9&"'!"&"AG4") -> 0 | DG9: =INDIRECT("'"&D9&"'!"&"AG5") -> 0 | DH9: =INDIRECT("'"&D9&"'!"&"AH3") -> 0 | DI9: =INDIRECT("'"&D9&"'!"&"AH4") -> 0 | DJ9: =INDIRECT("'"&D9&"'!"&"AH5") -> 0 | DK9: =INDIRECT("'"&D9&"'!"&"AF10") -> 0 | DL9: =INDIRECT("'"&D9&"'!"&"AG10") -> 0 | DM9: =INDIRECT("'"&D9&"'!"&"AH10") -> 0 | DO9: =(IF(INDIRECT("'"&D9&"'!"&"AD1")=0,"-","-RVC="&INDIRECT("'"&D9&"'!"&"AD1")))&IF(INDIRECT("'"&D9&"'!"&"AF1")=0,"-","-GCS="&INDIRECT("'"&D9&"'!"&"AF1")) -> --
C10: Bu_#1 | D10: Builder_Enhancement_3.1 | E10: =INDIRECT("'"&D10&"'!"&"C6") -> 0 | F10: =G10-E10 -> 110 | G10: =INDIRECT("'"&D10&"'!"&"C1") -> 110 | H10: =INDIRECT("'"&D10&"'!"&"C2") -> 109 | I10: =G10-H10 -> 1 | J10: =SUM(K10:L10) -> 0 | K10: =COUNTIFS(INDIRECT("'"&D10&"'!"&"$K$15:$K$1000"),"*Pass*") -> 0 | L10: =COUNTIFS(INDIRECT("'"&D10&"'!"&"$K$15:$K$1000"),"*Fail*") -> 0 | M10: =COUNTIFS(INDIRECT("'"&D10&"'!"&"$K$15:$K$1000"),"*skip*") -> 0 | N10: =INDIRECT("'"&D10&"'!"&"E3") -> 0 | O10: =(IF(INDIRECT("'"&D10&"'!"&"L3")=0,"-","-RVC="&INDIRECT("'"&D10&"'!"&"L3")&"-"))&IF(INDIRECT("'"&D10&"'!"&"L4")=0,"-","-GCS="&INDIRECT("'"&D10&"'!"&"L4")&"-") -> -- | Q10: =INDIRECT(CONCATENATE("'",$D10,"'!$AN$12")) -> N | R10: =SUM(S10:T10) -> 110 | S10: 109 | T10: 1 | U10: =IFERROR(V10/R10,"-") -> 1 | V10: =INDIRECT("'"&D10&"'!"&"P3") -> 110 | W10: =INDIRECT("'"&D10&"'!"&"P4") -> 110 | X10: =INDIRECT("'"&D10&"'!"&"P5") -> 0 | Y10: =INDIRECT("'"&D10&"'!"&"Q3") -> 109 | Z10: =INDIRECT("'"&D10&"'!"&"Q4") -> 109 | AA10: =INDIRECT("'"&D10&"'!"&"Q5") -> 0 | AB10: =INDIRECT("'"&D10&"'!"&"R3") -> 1 | AC10: =INDIRECT("'"&D10&"'!"&"R4") -> 1 | AD10: =INDIRECT("'"&D10&"'!"&"R5") -> 0 | AE10: =INDIRECT("'"&D10&"'!"&"P10") -> 0 | AF10: =INDIRECT("'"&D10&"'!"&"Q10") -> 0 | AG10: =INDIRECT("'"&D10&"'!"&"R10") -> 0 | AI10: =(IF(INDIRECT("'"&D10&"'!"&"P1")=0,"-","-RVC="&INDIRECT("'"&D10&"'!"&"P1")))&IF(INDIRECT("'"&D10&"'!"&"R1")=0,"-","-GCS="&INDIRECT("'"&D10&"'!"&"R1")) -> --GCS=110 | AK10: GCS | AL10: =INDIRECT(CONCATENATE("'",$D10,"'!$AR$3")) -> NOT-YET | AM10: =SUM(AN10:AO10) -> 110 | AN10: 109 | AO10: 1 | AP10: =IFERROR(AQ10/AM10,"-") -> 1 | AQ10: =INDIRECT("'"&D10&"'!"&"T3") -> 110 | AR10: =INDIRECT("'"&D10&"'!"&"T4") -> 110 | AS10: =INDIRECT("'"&D10&"'!"&"T5") -> 0 | AT10: =INDIRECT("'"&D10&"'!"&"U3") -> 109 | AU10: =INDIRECT("'"&D10&"'!"&"U4") -> 109 | AV10: =INDIRECT("'"&D10&"'!"&"U5") -> 0 | AW10: =INDIRECT("'"&D10&"'!"&"V3") -> 1 | AX10: =INDIRECT("'"&D10&"'!"&"V4") -> 1 | AY10: =INDIRECT("'"&D10&"'!"&"V5") -> 0 | AZ10: =INDIRECT("'"&D10&"'!"&"T10") -> 0 | BA10: =INDIRECT("'"&D10&"'!"&"U10") -> 0 | BB10: =INDIRECT("'"&D10&"'!"&"V10") -> 0 | BD10: =(IF(INDIRECT("'"&D10&"'!"&"T1")=0,"-","-RVC="&INDIRECT("'"&D10&"'!"&"T1")))&IF(INDIRECT("'"&D10&"'!"&"V1")=0,"-","-GCS="&INDIRECT("'"&D10&"'!"&"V1")) -> --GCS=110 | BF10: GCS | BG10: =INDIRECT(CONCATENATE("'",$D10,"'!$AR$4")) -> NOT-YET | BH10: =SUM(BI10:BJ10) -> 0 | BK10: =IFERROR(BL10/BH10,"-") -> - | BL10: =INDIRECT("'"&D10&"'!"&"X3") -> 0 | BM10: =INDIRECT("'"&D10&"'!"&"X4") -> 0 | BN10: =INDIRECT("'"&D10&"'!"&"X5") -> 0 | BO10: =INDIRECT("'"&D10&"'!"&"Y3") -> 0 | BP10: =INDIRECT("'"&D10&"'!"&"Y4") -> 0 | BQ10: =INDIRECT("'"&D10&"'!"&"Y5") -> 0 | BR10: =INDIRECT("'"&D10&"'!"&"Z3") -> 0 | BS10: =INDIRECT("'"&D10&"'!"&"Z4") -> 0 | BT10: =INDIRECT("'"&D10&"'!"&"Z5") -> 0 | BU10: =INDIRECT("'"&D10&"'!"&"X10") -> 0 | BV10: =INDIRECT("'"&D10&"'!"&"Y10") -> 0 | BW10: =INDIRECT("'"&D10&"'!"&"Z10") -> 0 | BY10: =(IF(INDIRECT("'"&D10&"'!"&"V1")=0,"-","-RVC="&INDIRECT("'"&D10&"'!"&"V1")))&IF(INDIRECT("'"&D10&"'!"&"X1")=0,"-","-GCS="&INDIRECT("'"&D10&"'!"&"X1")) -> -RVC=110- | CB10: =INDIRECT(CONCATENATE("'",$D10,"'!$AR$5")) -> NOT-YET | CC10: =SUM(CD10:CE10) -> 0 | CF10: =IFERROR(CG10/CC10,"-") -> - | CG10: =INDIRECT("'"&D10&"'!"&"AB3") -> 0 | CH10: =INDIRECT("'"&D10&"'!"&"AB4") -> 0 | CI10: =INDIRECT("'"&D10&"'!"&"AB5") -> 0 | CJ10: =INDIRECT("'"&D10&"'!"&"AC3") -> 0 | CK10: =INDIRECT("'"&D10&"'!"&"AC4") -> 0 | CL10: =INDIRECT("'"&D10&"'!"&"AC5") -> 0 | CM10: =INDIRECT("'"&D10&"'!"&"AD3") -> 0 | CN10: =INDIRECT("'"&D10&"'!"&"AD4") -> 0 | CO10: =INDIRECT("'"&D10&"'!"&"AD5") -> 0 | CP10: =INDIRECT("'"&D10&"'!"&"AB10") -> 0 | CQ10: =INDIRECT("'"&D10&"'!"&"AC10") -> 0 | CR10: =INDIRECT("'"&D10&"'!"&"AD10") -> 0 | CT10: =(IF(INDIRECT("'"&D10&"'!"&"Z1")=0,"-","-RVC="&INDIRECT("'"&D10&"'!"&"Z1")))&IF(INDIRECT("'"&D10&"'!"&"AB1")=0,"-","-GCS="&INDIRECT("'"&D10&"'!"&"AB1")) -> -- | CX10: =SUM(CY10:CZ10) -> 0 | DA10: =IFERROR(DB10/CX10,"-") -> - | DB10: =INDIRECT("'"&D10&"'!"&"AF3") -> 0 | DC10: =INDIRECT("'"&D10&"'!"&"AF4") -> 0 | DD10: =INDIRECT("'"&D10&"'!"&"AF5") -> 0 | DE10: =INDIRECT("'"&D10&"'!"&"AG3") -> 0 | DF10: =INDIRECT("'"&D10&"'!"&"AG4") -> 0 | DG10: =INDIRECT("'"&D10&"'!"&"AG5") -> 0 | DH10: =INDIRECT("'"&D10&"'!"&"AH3") -> 0 | DI10: =INDIRECT("'"&D10&"'!"&"AH4") -> 0 | DJ10: =INDIRECT("'"&D10&"'!"&"AH5") -> 0 | DK10: =INDIRECT("'"&D10&"'!"&"AF10") -> 0 | DL10: =INDIRECT("'"&D10&"'!"&"AG10") -> 0 | DM10: =INDIRECT("'"&D10&"'!"&"AH10") -> 0 | DO10: =(IF(INDIRECT("'"&D10&"'!"&"AD1")=0,"-","-RVC="&INDIRECT("'"&D10&"'!"&"AD1")))&IF(INDIRECT("'"&D10&"'!"&"AF1")=0,"-","-GCS="&INDIRECT("'"&D10&"'!"&"AF1")) -> --
C11: Bu_#1 | D11: Builder_Rename&ImportProject | E11: =INDIRECT("'"&D11&"'!"&"C6") -> 0 | F11: =G11-E11 -> 21 | G11: =INDIRECT("'"&D11&"'!"&"C1") -> 21 | H11: =INDIRECT("'"&D11&"'!"&"C2") -> 21 | I11: =G11-H11 -> 0 | J11: =SUM(K11:L11) -> 0 | K11: =COUNTIFS(INDIRECT("'"&D11&"'!"&"$K$15:$K$1000"),"*Pass*") -> 0 | L11: =COUNTIFS(INDIRECT("'"&D11&"'!"&"$K$15:$K$1000"),"*Fail*") -> 0 | M11: =COUNTIFS(INDIRECT("'"&D11&"'!"&"$K$15:$K$1000"),"*skip*") -> 0 | N11: =INDIRECT("'"&D11&"'!"&"E3") -> 0 | O11: =(IF(INDIRECT("'"&D11&"'!"&"L3")=0,"-","-RVC="&INDIRECT("'"&D11&"'!"&"L3")&"-"))&IF(INDIRECT("'"&D11&"'!"&"L4")=0,"-","-GCS="&INDIRECT("'"&D11&"'!"&"L4")&"-") -> -- | Q11: =INDIRECT(CONCATENATE("'",$D11,"'!$AN$12")) -> NOT-YET | R11: =SUM(S11:T11) -> 21 | S11: 21 | T11: 0 | U11: =IFERROR(V11/R11,"-") -> 1 | V11: =INDIRECT("'"&D11&"'!"&"P3") -> 21 | W11: =INDIRECT("'"&D11&"'!"&"P4") -> 21 | X11: =INDIRECT("'"&D11&"'!"&"P5") -> 0 | Y11: =INDIRECT("'"&D11&"'!"&"Q3") -> 21 | Z11: =INDIRECT("'"&D11&"'!"&"Q4") -> 21 | AA11: =INDIRECT("'"&D11&"'!"&"Q5") -> 0 | AB11: =INDIRECT("'"&D11&"'!"&"R3") -> 0 | AC11: =INDIRECT("'"&D11&"'!"&"R4") -> 0 | AD11: =INDIRECT("'"&D11&"'!"&"R5") -> 0 | AE11: =INDIRECT("'"&D11&"'!"&"P10") -> 0 | AF11: =INDIRECT("'"&D11&"'!"&"Q10") -> 0 | AG11: =INDIRECT("'"&D11&"'!"&"R10") -> 0 | AI11: =(IF(INDIRECT("'"&D11&"'!"&"P1")=0,"-","-RVC="&INDIRECT("'"&D11&"'!"&"P1")))&IF(INDIRECT("'"&D11&"'!"&"R1")=0,"-","-GCS="&INDIRECT("'"&D11&"'!"&"R1")) -> --GCS=21 | AK11: GCS | AL11: =INDIRECT(CONCATENATE("'",$D11,"'!$AR$3")) -> NOT-YET | AM11: =SUM(AN11:AO11) -> 21 | AN11: 21 | AO11: 0 | AP11: =IFERROR(AQ11/AM11,"-") -> 1 | AQ11: =INDIRECT("'"&D11&"'!"&"T3") -> 21 | AR11: =INDIRECT("'"&D11&"'!"&"T4") -> 21 | AS11: =INDIRECT("'"&D11&"'!"&"T5") -> 0 | AT11: =INDIRECT("'"&D11&"'!"&"U3") -> 21 | AU11: =INDIRECT("'"&D11&"'!"&"U4") -> 21 | AV11: =INDIRECT("'"&D11&"'!"&"U5") -> 0 | AW11: =INDIRECT("'"&D11&"'!"&"V3") -> 0 | AX11: =INDIRECT("'"&D11&"'!"&"V4") -> 0 | AY11: =INDIRECT("'"&D11&"'!"&"V5") -> 0 | AZ11: =INDIRECT("'"&D11&"'!"&"T10") -> 0 | BA11: =INDIRECT("'"&D11&"'!"&"U10") -> 0 | BB11: =INDIRECT("'"&D11&"'!"&"V10") -> 0 | BD11: =(IF(INDIRECT("'"&D11&"'!"&"T1")=0,"-","-RVC="&INDIRECT("'"&D11&"'!"&"T1")))&IF(INDIRECT("'"&D11&"'!"&"V1")=0,"-","-GCS="&INDIRECT("'"&D11&"'!"&"V1")) -> --GCS=21 | BF11: GCS | BG11: =INDIRECT(CONCATENATE("'",$D11,"'!$AR$4")) -> NOT-YET | BH11: =SUM(BI11:BJ11) -> 0 | BK11: =IFERROR(BL11/BH11,"-") -> - | BL11: =INDIRECT("'"&D11&"'!"&"X3") -> 0 | BM11: =INDIRECT("'"&D11&"'!"&"X4") -> 0 | BN11: =INDIRECT("'"&D11&"'!"&"X5") -> 0 | BO11: =INDIRECT("'"&D11&"'!"&"Y3") -> 0 | BP11: =INDIRECT("'"&D11&"'!"&"Y4") -> 0 | BQ11: =INDIRECT("'"&D11&"'!"&"Y5") -> 0 | BR11: =INDIRECT("'"&D11&"'!"&"Z3") -> 0 | BS11: =INDIRECT("'"&D11&"'!"&"Z4") -> 0 | BT11: =INDIRECT("'"&D11&"'!"&"Z5") -> 0 | BU11: =INDIRECT("'"&D11&"'!"&"X10") -> 0 | BV11: =INDIRECT("'"&D11&"'!"&"Y10") -> 0 | BW11: =INDIRECT("'"&D11&"'!"&"Z10") -> 0 | BY11: =(IF(INDIRECT("'"&D11&"'!"&"V1")=0,"-","-RVC="&INDIRECT("'"&D11&"'!"&"V1")))&IF(INDIRECT("'"&D11&"'!"&"X1")=0,"-","-GCS="&INDIRECT("'"&D11&"'!"&"X1")) -> -RVC=21- | CB11: =INDIRECT(CONCATENATE("'",$D11,"'!$AR$5")) -> NOT-YET | CC11: =SUM(CD11:CE11) -> 0 | CF11: =IFERROR(CG11/CC11,"-") -> - | CG11: =INDIRECT("'"&D11&"'!"&"AB3") -> 0 | CH11: =INDIRECT("'"&D11&"'!"&"AB4") -> 0 | CI11: =INDIRECT("'"&D11&"'!"&"AB5") -> 0 | CJ11: =INDIRECT("'"&D11&"'!"&"AC3") -> 0 | CK11: =INDIRECT("'"&D11&"'!"&"AC4") -> 0 | CL11: =INDIRECT("'"&D11&"'!"&"AC5") -> 0 | CM11: =INDIRECT("'"&D11&"'!"&"AD3") -> 0 | CN11: =INDIRECT("'"&D11&"'!"&"AD4") -> 0 | CO11: =INDIRECT("'"&D11&"'!"&"AD5") -> 0 | CP11: =INDIRECT("'"&D11&"'!"&"AB10") -> 0 | CQ11: =INDIRECT("'"&D11&"'!"&"AC10") -> 0 | CR11: =INDIRECT("'"&D11&"'!"&"AD10") -> 0 | CT11: =(IF(INDIRECT("'"&D11&"'!"&"Z1")=0,"-","-RVC="&INDIRECT("'"&D11&"'!"&"Z1")))&IF(INDIRECT("'"&D11&"'!"&"AB1")=0,"-","-GCS="&INDIRECT("'"&D11&"'!"&"AB1")) -> -- | CX11: =SUM(CY11:CZ11) -> 0 | DA11: =IFERROR(DB11/CX11,"-") -> - | DB11: =INDIRECT("'"&D11&"'!"&"AF3") -> 0 | DC11: =INDIRECT("'"&D11&"'!"&"AF4") -> 0 | DD11: =INDIRECT("'"&D11&"'!"&"AF5") -> 0 | DE11: =INDIRECT("'"&D11&"'!"&"AG3") -> 0 | DF11: =INDIRECT("'"&D11&"'!"&"AG4") -> 0 | DG11: =INDIRECT("'"&D11&"'!"&"AG5") -> 0 | DH11: =INDIRECT("'"&D11&"'!"&"AH3") -> 0 | DI11: =INDIRECT("'"&D11&"'!"&"AH4") -> 0 | DJ11: =INDIRECT("'"&D11&"'!"&"AH5") -> 0 | DK11: =INDIRECT("'"&D11&"'!"&"AF10") -> 0 | DL11: =INDIRECT("'"&D11&"'!"&"AG10") -> 0 | DM11: =INDIRECT("'"&D11&"'!"&"AH10") -> 0 | DO11: =(IF(INDIRECT("'"&D11&"'!"&"AD1")=0,"-","-RVC="&INDIRECT("'"&D11&"'!"&"AD1")))&IF(INDIRECT("'"&D11&"'!"&"AF1")=0,"-","-GCS="&INDIRECT("'"&D11&"'!"&"AF1")) -> --
C12: Bu_#1 | D12: Builder_SimultaneousBuild | E12: =INDIRECT("'"&D12&"'!"&"C6") -> 0 | F12: =G12-E12 -> 60 | G12: =INDIRECT("'"&D12&"'!"&"C1") -> 60 | H12: =INDIRECT("'"&D12&"'!"&"C2") -> 60 | I12: =G12-H12 -> 0 | J12: =SUM(K12:L12) -> 0 | K12: =COUNTIFS(INDIRECT("'"&D12&"'!"&"$K$15:$K$1000"),"*Pass*") -> 0 | L12: =COUNTIFS(INDIRECT("'"&D12&"'!"&"$K$15:$K$1000"),"*Fail*") -> 0 | M12: =COUNTIFS(INDIRECT("'"&D12&"'!"&"$K$15:$K$1000"),"*skip*") -> 0 | N12: =INDIRECT("'"&D12&"'!"&"E3") -> 0 | O12: =(IF(INDIRECT("'"&D12&"'!"&"L3")=0,"-","-RVC="&INDIRECT("'"&D12&"'!"&"L3")&"-"))&IF(INDIRECT("'"&D12&"'!"&"L4")=0,"-","-GCS="&INDIRECT("'"&D12&"'!"&"L4")&"-") -> -- | Q12: =INDIRECT(CONCATENATE("'",$D12,"'!$AN$12")) -> NOT-YET | R12: =SUM(S12:T12) -> 60 | S12: 60 | T12: 0 | U12: =IFERROR(V12/R12,"-") -> 1 | V12: =INDIRECT("'"&D12&"'!"&"P3") -> 60 | W12: =INDIRECT("'"&D12&"'!"&"P4") -> 60 | X12: =INDIRECT("'"&D12&"'!"&"P5") -> 0 | Y12: =INDIRECT("'"&D12&"'!"&"Q3") -> 60 | Z12: =INDIRECT("'"&D12&"'!"&"Q4") -> 60 | AA12: =INDIRECT("'"&D12&"'!"&"Q5") -> 0 | AB12: =INDIRECT("'"&D12&"'!"&"R3") -> 0 | AC12: =INDIRECT("'"&D12&"'!"&"R4") -> 0 | AD12: =INDIRECT("'"&D12&"'!"&"R5") -> 0 | AE12: =INDIRECT("'"&D12&"'!"&"P10") -> 0 | AF12: =INDIRECT("'"&D12&"'!"&"Q10") -> 0 | AG12: =INDIRECT("'"&D12&"'!"&"R10") -> 0 | AI12: =(IF(INDIRECT("'"&D12&"'!"&"P1")=0,"-","-RVC="&INDIRECT("'"&D12&"'!"&"P1")))&IF(INDIRECT("'"&D12&"'!"&"R1")=0,"-","-GCS="&INDIRECT("'"&D12&"'!"&"R1")) -> --GCS=60 | AK12: GCS | AL12: =INDIRECT(CONCATENATE("'",$D12,"'!$AR$3")) -> NOT-YET | AM12: =SUM(AN12:AO12) -> 60 | AN12: 60 | AO12: 0 | AP12: =IFERROR(AQ12/AM12,"-") -> 1 | AQ12: =INDIRECT("'"&D12&"'!"&"T3") -> 60 | AR12: =INDIRECT("'"&D12&"'!"&"T4") -> 60 | AS12: =INDIRECT("'"&D12&"'!"&"T5") -> 0 | AT12: =INDIRECT("'"&D12&"'!"&"U3") -> 60 | AU12: =INDIRECT("'"&D12&"'!"&"U4") -> 60 | AV12: =INDIRECT("'"&D12&"'!"&"U5") -> 0 | AW12: =INDIRECT("'"&D12&"'!"&"V3") -> 0 | AX12: =INDIRECT("'"&D12&"'!"&"V4") -> 0 | AY12: =INDIRECT("'"&D12&"'!"&"V5") -> 0 | AZ12: =INDIRECT("'"&D12&"'!"&"T10") -> 0 | BA12: =INDIRECT("'"&D12&"'!"&"U10") -> 0 | BB12: =INDIRECT("'"&D12&"'!"&"V10") -> 0 | BD12: =(IF(INDIRECT("'"&D12&"'!"&"T1")=0,"-","-RVC="&INDIRECT("'"&D12&"'!"&"T1")))&IF(INDIRECT("'"&D12&"'!"&"V1")=0,"-","-GCS="&INDIRECT("'"&D12&"'!"&"V1")) -> --GCS=60 | BF12: GCS | BG12: =INDIRECT(CONCATENATE("'",$D12,"'!$AR$4")) -> NOT-YET | BH12: =SUM(BI12:BJ12) -> 0 | BK12: =IFERROR(BL12/BH12,"-") -> - | BL12: =INDIRECT("'"&D12&"'!"&"X3") -> 0 | BM12: =INDIRECT("'"&D12&"'!"&"X4") -> 0 | BN12: =INDIRECT("'"&D12&"'!"&"X5") -> 0 | BO12: =INDIRECT("'"&D12&"'!"&"Y3") -> 0 | BP12: =INDIRECT("'"&D12&"'!"&"Y4") -> 0 | BQ12: =INDIRECT("'"&D12&"'!"&"Y5") -> 0 | BR12: =INDIRECT("'"&D12&"'!"&"Z3") -> 0 | BS12: =INDIRECT("'"&D12&"'!"&"Z4") -> 0 | BT12: =INDIRECT("'"&D12&"'!"&"Z5") -> 0 | BU12: =INDIRECT("'"&D12&"'!"&"X10") -> 0 | BV12: =INDIRECT("'"&D12&"'!"&"Y10") -> 0 | BW12: =INDIRECT("'"&D12&"'!"&"Z10") -> 0 | BY12: =(IF(INDIRECT("'"&D12&"'!"&"V1")=0,"-","-RVC="&INDIRECT("'"&D12&"'!"&"V1")))&IF(INDIRECT("'"&D12&"'!"&"X1")=0,"-","-GCS="&INDIRECT("'"&D12&"'!"&"X1")) -> -RVC=60- | CB12: =INDIRECT(CONCATENATE("'",$D12,"'!$AR$5")) -> NOT-YET | CC12: =SUM(CD12:CE12) -> 0 | CF12: =IFERROR(CG12/CC12,"-") -> - | CG12: =INDIRECT("'"&D12&"'!"&"AB3") -> 0 | CH12: =INDIRECT("'"&D12&"'!"&"AB4") -> 0 | CI12: =INDIRECT("'"&D12&"'!"&"AB5") -> 0 | CJ12: =INDIRECT("'"&D12&"'!"&"AC3") -> 0 | CK12: =INDIRECT("'"&D12&"'!"&"AC4") -> 0 | CL12: =INDIRECT("'"&D12&"'!"&"AC5") -> 0 | CM12: =INDIRECT("'"&D12&"'!"&"AD3") -> 0 | CN12: =INDIRECT("'"&D12&"'!"&"AD4") -> 0 | CO12: =INDIRECT("'"&D12&"'!"&"AD5") -> 0 | CP12: =INDIRECT("'"&D12&"'!"&"AB10") -> 0 | CQ12: =INDIRECT("'"&D12&"'!"&"AC10") -> 0 | CR12: =INDIRECT("'"&D12&"'!"&"AD10") -> 0 | CT12: =(IF(INDIRECT("'"&D12&"'!"&"Z1")=0,"-","-RVC="&INDIRECT("'"&D12&"'!"&"Z1")))&IF(INDIRECT("'"&D12&"'!"&"AB1")=0,"-","-GCS="&INDIRECT("'"&D12&"'!"&"AB1")) -> -- | CX12: =SUM(CY12:CZ12) -> 0 | DA12: =IFERROR(DB12/CX12,"-") -> - | DB12: =INDIRECT("'"&D12&"'!"&"AF3") -> 0 | DC12: =INDIRECT("'"&D12&"'!"&"AF4") -> 0 | DD12: =INDIRECT("'"&D12&"'!"&"AF5") -> 0 | DE12: =INDIRECT("'"&D12&"'!"&"AG3") -> 0 | DF12: =INDIRECT("'"&D12&"'!"&"AG4") -> 0 | DG12: =INDIRECT("'"&D12&"'!"&"AG5") -> 0 | DH12: =INDIRECT("'"&D12&"'!"&"AH3") -> 0 | DI12: =INDIRECT("'"&D12&"'!"&"AH4") -> 0 | DJ12: =INDIRECT("'"&D12&"'!"&"AH5") -> 0 | DK12: =INDIRECT("'"&D12&"'!"&"AF10") -> 0 | DL12: =INDIRECT("'"&D12&"'!"&"AG10") -> 0 | DM12: =INDIRECT("'"&D12&"'!"&"AH10") -> 0 | DO12: =(IF(INDIRECT("'"&D12&"'!"&"AD1")=0,"-","-RVC="&INDIRECT("'"&D12&"'!"&"AD1")))&IF(INDIRECT("'"&D12&"'!"&"AF1")=0,"-","-GCS="&INDIRECT("'"&D12&"'!"&"AF1")) -> --
C13: Bu_#1 | D13: Toolchain_Management_Regression | E13: =INDIRECT("'"&D13&"'!"&"C6") -> 0 | F13: =G13-E13 -> 29 | G13: =INDIRECT("'"&D13&"'!"&"C1") -> 29 | H13: =INDIRECT("'"&D13&"'!"&"C2") -> 0 | I13: =G13-H13 -> 29 | J13: =SUM(K13:L13) -> 0 | K13: =COUNTIFS(INDIRECT("'"&D13&"'!"&"$K$15:$K$1000"),"*Pass*") -> 0 | L13: =COUNTIFS(INDIRECT("'"&D13&"'!"&"$K$15:$K$1000"),"*Fail*") -> 0 | M13: =COUNTIFS(INDIRECT("'"&D13&"'!"&"$K$15:$K$1000"),"*skip*") -> 0 | N13: =INDIRECT("'"&D13&"'!"&"E3") -> 0 | O13: =(IF(INDIRECT("'"&D13&"'!"&"L3")=0,"-","-RVC="&INDIRECT("'"&D13&"'!"&"L3")&"-"))&IF(INDIRECT("'"&D13&"'!"&"L4")=0,"-","-GCS="&INDIRECT("'"&D13&"'!"&"L4")&"-") -> -- | Q13: =INDIRECT(CONCATENATE("'",$D13,"'!$AN$12")) -> N | R13: =SUM(S13:T13) -> 29 | S13: 0 | T13: 29 | U13: =IFERROR(V13/R13,"-") -> 1 | V13: =INDIRECT("'"&D13&"'!"&"P3") -> 29 | W13: =INDIRECT("'"&D13&"'!"&"P4") -> 29 | X13: =INDIRECT("'"&D13&"'!"&"P5") -> 0 | Y13: =INDIRECT("'"&D13&"'!"&"Q3") -> 0 | Z13: =INDIRECT("'"&D13&"'!"&"Q4") -> 0 | AA13: =INDIRECT("'"&D13&"'!"&"Q5") -> 0 | AB13: =INDIRECT("'"&D13&"'!"&"R3") -> 29 | AC13: =INDIRECT("'"&D13&"'!"&"R4") -> 29 | AD13: =INDIRECT("'"&D13&"'!"&"R5") -> 0 | AE13: =INDIRECT("'"&D13&"'!"&"P10") -> 0 | AF13: =INDIRECT("'"&D13&"'!"&"Q10") -> 0 | AG13: =INDIRECT("'"&D13&"'!"&"R10") -> 0 | AI13: =(IF(INDIRECT("'"&D13&"'!"&"P1")=0,"-","-RVC="&INDIRECT("'"&D13&"'!"&"P1")))&IF(INDIRECT("'"&D13&"'!"&"R1")=0,"-","-GCS="&INDIRECT("'"&D13&"'!"&"R1")) -> --GCS=29 | AK13: GCS | AL13: =INDIRECT(CONCATENATE("'",$D13,"'!$AR$3")) -> E | AM13: =SUM(AN13:AO13) -> 29 | AN13: 0 | AO13: 29 | AP13: =IFERROR(AQ13/AM13,"-") -> 1 | AQ13: =INDIRECT("'"&D13&"'!"&"T3") -> 29 | AR13: =INDIRECT("'"&D13&"'!"&"T4") -> 29 | AS13: =INDIRECT("'"&D13&"'!"&"T5") -> 0 | AT13: =INDIRECT("'"&D13&"'!"&"U3") -> 0 | AU13: =INDIRECT("'"&D13&"'!"&"U4") -> 0 | AV13: =INDIRECT("'"&D13&"'!"&"U5") -> 0 | AW13: =INDIRECT("'"&D13&"'!"&"V3") -> 29 | AX13: =INDIRECT("'"&D13&"'!"&"V4") -> 29 | AY13: =INDIRECT("'"&D13&"'!"&"V5") -> 0 | AZ13: =INDIRECT("'"&D13&"'!"&"T10") -> 0 | BA13: =INDIRECT("'"&D13&"'!"&"U10") -> 0 | BB13: =INDIRECT("'"&D13&"'!"&"V10") -> 0 | BD13: =(IF(INDIRECT("'"&D13&"'!"&"T1")=0,"-","-RVC="&INDIRECT("'"&D13&"'!"&"T1")))&IF(INDIRECT("'"&D13&"'!"&"V1")=0,"-","-GCS="&INDIRECT("'"&D13&"'!"&"V1")) -> --GCS=29 | BF13: GCS | BG13: =INDIRECT(CONCATENATE("'",$D13,"'!$AR$4")) -> E | BH13: =SUM(BI13:BJ13) -> 0 | BK13: =IFERROR(BL13/BH13,"-") -> - | BL13: =INDIRECT("'"&D13&"'!"&"X3") -> 0 | BM13: =INDIRECT("'"&D13&"'!"&"X4") -> 0 | BN13: =INDIRECT("'"&D13&"'!"&"X5") -> 0 | BO13: =INDIRECT("'"&D13&"'!"&"Y3") -> 0 | BP13: =INDIRECT("'"&D13&"'!"&"Y4") -> 0 | BQ13: =INDIRECT("'"&D13&"'!"&"Y5") -> 0 | BR13: =INDIRECT("'"&D13&"'!"&"Z3") -> 0 | BS13: =INDIRECT("'"&D13&"'!"&"Z4") -> 0 | BT13: =INDIRECT("'"&D13&"'!"&"Z5") -> 0 | BU13: =INDIRECT("'"&D13&"'!"&"X10") -> 0 | BV13: =INDIRECT("'"&D13&"'!"&"Y10") -> 0 | BW13: =INDIRECT("'"&D13&"'!"&"Z10") -> 0 | BY13: =(IF(INDIRECT("'"&D13&"'!"&"V1")=0,"-","-RVC="&INDIRECT("'"&D13&"'!"&"V1")))&IF(INDIRECT("'"&D13&"'!"&"X1")=0,"-","-GCS="&INDIRECT("'"&D13&"'!"&"X1")) -> -RVC=29- | CB13: =INDIRECT(CONCATENATE("'",$D13,"'!$AR$5")) -> NOT-YET | CC13: =SUM(CD13:CE13) -> 0 | CF13: =IFERROR(CG13/CC13,"-") -> - | CG13: =INDIRECT("'"&D13&"'!"&"AB3") -> 0 | CH13: =INDIRECT("'"&D13&"'!"&"AB4") -> 0 | CI13: =INDIRECT("'"&D13&"'!"&"AB5") -> 0 | CJ13: =INDIRECT("'"&D13&"'!"&"AC3") -> 0 | CK13: =INDIRECT("'"&D13&"'!"&"AC4") -> 0 | CL13: =INDIRECT("'"&D13&"'!"&"AC5") -> 0 | CM13: =INDIRECT("'"&D13&"'!"&"AD3") -> 0 | CN13: =INDIRECT("'"&D13&"'!"&"AD4") -> 0 | CO13: =INDIRECT("'"&D13&"'!"&"AD5") -> 0 | CP13: =INDIRECT("'"&D13&"'!"&"AB10") -> 0 | CQ13: =INDIRECT("'"&D13&"'!"&"AC10") -> 0 | CR13: =INDIRECT("'"&D13&"'!"&"AD10") -> 0 | CT13: =(IF(INDIRECT("'"&D13&"'!"&"Z1")=0,"-","-RVC="&INDIRECT("'"&D13&"'!"&"Z1")))&IF(INDIRECT("'"&D13&"'!"&"AB1")=0,"-","-GCS="&INDIRECT("'"&D13&"'!"&"AB1")) -> -- | CX13: =SUM(CY13:CZ13) -> 0 | DA13: =IFERROR(DB13/CX13,"-") -> - | DB13: =INDIRECT("'"&D13&"'!"&"AF3") -> 0 | DC13: =INDIRECT("'"&D13&"'!"&"AF4") -> 0 | DD13: =INDIRECT("'"&D13&"'!"&"AF5") -> 0 | DE13: =INDIRECT("'"&D13&"'!"&"AG3") -> 0 | DF13: =INDIRECT("'"&D13&"'!"&"AG4") -> 0 | DG13: =INDIRECT("'"&D13&"'!"&"AG5") -> 0 | DH13: =INDIRECT("'"&D13&"'!"&"AH3") -> 0 | DI13: =INDIRECT("'"&D13&"'!"&"AH4") -> 0 | DJ13: =INDIRECT("'"&D13&"'!"&"AH5") -> 0 | DK13: =INDIRECT("'"&D13&"'!"&"AF10") -> 0 | DL13: =INDIRECT("'"&D13&"'!"&"AG10") -> 0 | DM13: =INDIRECT("'"&D13&"'!"&"AH10") -> 0 | DO13: =(IF(INDIRECT("'"&D13&"'!"&"AD1")=0,"-","-RVC="&INDIRECT("'"&D13&"'!"&"AD1")))&IF(INDIRECT("'"&D13&"'!"&"AF1")=0,"-","-GCS="&INDIRECT("'"&D13&"'!"&"AF1")) -> --
C14: Bu_#1 | D14: CustomPhases | E14: =INDIRECT("'"&D14&"'!"&"C6") -> 0 | F14: =G14-E14 -> 11 | G14: =INDIRECT("'"&D14&"'!"&"C1") -> 11 | H14: =INDIRECT("'"&D14&"'!"&"C2") -> 0 | I14: =G14-H14 -> 11 | J14: =SUM(K14:L14) -> 0 | K14: =COUNTIFS(INDIRECT("'"&D14&"'!"&"$K$15:$K$1000"),"*Pass*") -> 0 | L14: =COUNTIFS(INDIRECT("'"&D14&"'!"&"$K$15:$K$1000"),"*Fail*") -> 0 | M14: =COUNTIFS(INDIRECT("'"&D14&"'!"&"$K$15:$K$1000"),"*skip*") -> 0 | N14: =INDIRECT("'"&D14&"'!"&"E3") -> 0 | O14: =(IF(INDIRECT("'"&D14&"'!"&"L3")=0,"-","-RVC="&INDIRECT("'"&D14&"'!"&"L3")&"-"))&IF(INDIRECT("'"&D14&"'!"&"L4")=0,"-","-GCS="&INDIRECT("'"&D14&"'!"&"L4")&"-") -> -- | Q14: =INDIRECT(CONCATENATE("'",$D14,"'!$AN$12")) -> E | R14: =SUM(S14:T14) -> 11 | S14: 0 | T14: 11 | U14: =IFERROR(V14/R14,"-") -> 1 | V14: =INDIRECT("'"&D14&"'!"&"P3") -> 11 | W14: =INDIRECT("'"&D14&"'!"&"P4") -> 11 | X14: =INDIRECT("'"&D14&"'!"&"P5") -> 0 | Y14: =INDIRECT("'"&D14&"'!"&"Q3") -> 0 | Z14: =INDIRECT("'"&D14&"'!"&"Q4") -> 0 | AA14: =INDIRECT("'"&D14&"'!"&"Q5") -> 0 | AB14: =INDIRECT("'"&D14&"'!"&"R3") -> 11 | AC14: =INDIRECT("'"&D14&"'!"&"R4") -> 11 | AD14: =INDIRECT("'"&D14&"'!"&"R5") -> 0 | AE14: =INDIRECT("'"&D14&"'!"&"P10") -> 0 | AF14: =INDIRECT("'"&D14&"'!"&"Q10") -> 0 | AG14: =INDIRECT("'"&D14&"'!"&"R10") -> 0 | AI14: =(IF(INDIRECT("'"&D14&"'!"&"P1")=0,"-","-RVC="&INDIRECT("'"&D14&"'!"&"P1")))&IF(INDIRECT("'"&D14&"'!"&"R1")=0,"-","-GCS="&INDIRECT("'"&D14&"'!"&"R1")) -> --GCS=11 | AK14: GCS | AL14: =INDIRECT(CONCATENATE("'",$D14,"'!$AR$3")) -> NOT-YET | AM14: =SUM(AN14:AO14) -> 11 | AN14: 0 | AO14: 11 | AP14: =IFERROR(AQ14/AM14,"-") -> 1 | AQ14: =INDIRECT("'"&D14&"'!"&"T3") -> 11 | AR14: =INDIRECT("'"&D14&"'!"&"T4") -> 11 | AS14: =INDIRECT("'"&D14&"'!"&"T5") -> 0 | AT14: =INDIRECT("'"&D14&"'!"&"U3") -> 0 | AU14: =INDIRECT("'"&D14&"'!"&"U4") -> 0 | AV14: =INDIRECT("'"&D14&"'!"&"U5") -> 0 | AW14: =INDIRECT("'"&D14&"'!"&"V3") -> 11 | AX14: =INDIRECT("'"&D14&"'!"&"V4") -> 11 | AY14: =INDIRECT("'"&D14&"'!"&"V5") -> 0 | AZ14: =INDIRECT("'"&D14&"'!"&"T10") -> 0 | BA14: =INDIRECT("'"&D14&"'!"&"U10") -> 0 | BB14: =INDIRECT("'"&D14&"'!"&"V10") -> 0 | BD14: =(IF(INDIRECT("'"&D14&"'!"&"T1")=0,"-","-RVC="&INDIRECT("'"&D14&"'!"&"T1")))&IF(INDIRECT("'"&D14&"'!"&"V1")=0,"-","-GCS="&INDIRECT("'"&D14&"'!"&"V1")) -> --GCS=11 | BF14: GCS | BG14: =INDIRECT(CONCATENATE("'",$D14,"'!$AR$4")) -> NOT-YET | BH14: =SUM(BI14:BJ14) -> 0 | BK14: =IFERROR(BL14/BH14,"-") -> - | BL14: =INDIRECT("'"&D14&"'!"&"X3") -> 0 | BM14: =INDIRECT("'"&D14&"'!"&"X4") -> 0 | BN14: =INDIRECT("'"&D14&"'!"&"X5") -> 0 | BO14: =INDIRECT("'"&D14&"'!"&"Y3") -> 0 | BP14: =INDIRECT("'"&D14&"'!"&"Y4") -> 0 | BQ14: =INDIRECT("'"&D14&"'!"&"Y5") -> 0 | BR14: =INDIRECT("'"&D14&"'!"&"Z3") -> 0 | BS14: =INDIRECT("'"&D14&"'!"&"Z4") -> 0 | BT14: =INDIRECT("'"&D14&"'!"&"Z5") -> 0 | BU14: =INDIRECT("'"&D14&"'!"&"X10") -> 0 | BV14: =INDIRECT("'"&D14&"'!"&"Y10") -> 0 | BW14: =INDIRECT("'"&D14&"'!"&"Z10") -> 0 | BY14: =(IF(INDIRECT("'"&D14&"'!"&"V1")=0,"-","-RVC="&INDIRECT("'"&D14&"'!"&"V1")))&IF(INDIRECT("'"&D14&"'!"&"X1")=0,"-","-GCS="&INDIRECT("'"&D14&"'!"&"X1")) -> -RVC=11- | CB14: =INDIRECT(CONCATENATE("'",$D14,"'!$AR$5")) -> NOT-YET | CC14: =SUM(CD14:CE14) -> 0 | CF14: =IFERROR(CG14/CC14,"-") -> - | CG14: =INDIRECT("'"&D14&"'!"&"AB3") -> 0 | CH14: =INDIRECT("'"&D14&"'!"&"AB4") -> 0 | CI14: =INDIRECT("'"&D14&"'!"&"AB5") -> 0 | CJ14: =INDIRECT("'"&D14&"'!"&"AC3") -> 0 | CK14: =INDIRECT("'"&D14&"'!"&"AC4") -> 0 | CL14: =INDIRECT("'"&D14&"'!"&"AC5") -> 0 | CM14: =INDIRECT("'"&D14&"'!"&"AD3") -> 0 | CN14: =INDIRECT("'"&D14&"'!"&"AD4") -> 0 | CO14: =INDIRECT("'"&D14&"'!"&"AD5") -> 0 | CP14: =INDIRECT("'"&D14&"'!"&"AB10") -> 0 | CQ14: =INDIRECT("'"&D14&"'!"&"AC10") -> 0 | CR14: =INDIRECT("'"&D14&"'!"&"AD10") -> 0 | CT14: =(IF(INDIRECT("'"&D14&"'!"&"Z1")=0,"-","-RVC="&INDIRECT("'"&D14&"'!"&"Z1")))&IF(INDIRECT("'"&D14&"'!"&"AB1")=0,"-","-GCS="&INDIRECT("'"&D14&"'!"&"AB1")) -> -- | CX14: =SUM(CY14:CZ14) -> 0 | DA14: =IFERROR(DB14/CX14,"-") -> - | DB14: =INDIRECT("'"&D14&"'!"&"AF3") -> 0 | DC14: =INDIRECT("'"&D14&"'!"&"AF4") -> 0 | DD14: =INDIRECT("'"&D14&"'!"&"AF5") -> 0 | DE14: =INDIRECT("'"&D14&"'!"&"AG3") -> 0 | DF14: =INDIRECT("'"&D14&"'!"&"AG4") -> 0 | DG14: =INDIRECT("'"&D14&"'!"&"AG5") -> 0 | DH14: =INDIRECT("'"&D14&"'!"&"AH3") -> 0 | DI14: =INDIRECT("'"&D14&"'!"&"AH4") -> 0 | DJ14: =INDIRECT("'"&D14&"'!"&"AH5") -> 0 | DK14: =INDIRECT("'"&D14&"'!"&"AF10") -> 0 | DL14: =INDIRECT("'"&D14&"'!"&"AG10") -> 0 | DM14: =INDIRECT("'"&D14&"'!"&"AH10") -> 0 | DO14: =(IF(INDIRECT("'"&D14&"'!"&"AD1")=0,"-","-RVC="&INDIRECT("'"&D14&"'!"&"AD1")))&IF(INDIRECT("'"&D14&"'!"&"AF1")=0,"-","-GCS="&INDIRECT("'"&D14&"'!"&"AF1")) -> --

Sheet Builder_Common
A1: Total test cases | C1: =COUNTA($D$15:$D$1000)-COUNTIF($K$15:$K$1000,"-") -> 157 | D1: [Auto limitation] | E1: =COUNTIF($L$15:$L$1000,D1) -> 0 | O1: RVC | P1: =COUNTIFS(Q15:Q1000,"*RVC*") -> 0 | Q1: GCS | R1: =COUNTIFS(Q15:Q1000,"*GCS*") -> 157 | S1: RVC | T1: =COUNTIFS(U15:U1000,"*RVC*") -> 0 | U1: GCS | V1: =COUNTIFS(U15:U1000,"*GCS*") -> 157 | W1: RVC | X1: =COUNTIFS(Y15:Y1000,"*RVC*") -> 0 | Y1: GCS | Z1: =COUNTIFS(Y15:Y1000,"*GCS*") -> 0 | AA1: RVC | AB1: =COUNTIFS(AC15:AC1000,"*RVC*") -> 0 | AC1: GCS | AD1: =COUNTIFS(AC15:AC1000,"*GCS*") -> 0 | AE1: RVC | AF1: =COUNTIFS(AG15:AG1000,"*RVC*") -> 0 | AG1: GCS | AH1: =COUNTIFS(AG15:AG1000,"*GCS*") -> 0
B2: Auto | C2: =SUM(COUNTIF($L$15:$L$1000,{"*Ju*","*RCP*"})) -> 139 | D2: [Lack of equipment] | E2: =COUNTIF($L$15:$L$1000,D2) -> 0 | P2: Total | Q2: Auto | R2: Manual | T2: Total | U2: Auto | V2: Manual | X2: Total | Y2: Auto | Z2: Manual | AB2: Total | AC2: Auto | AD2: Manual | AF2: Total | AG2: Auto | AH2: Manual | AI2: Time | AJ2: Tester | AK2: Num of TC | AM2: Select the RUN: | AN2: =Summary!P2 -> 1 | AO2: Total time | AP2: Total TCs | AQ2: Average time | AR2: Deff. Level
B3: Manual | C3: =C1-C2 -> 18 | H3: Deff. Level | I3: TCs | J3: Time | M3: RVC | N3: =COUNTIFS($N$15:$N$1000,"*RVC*") -> 0 | O3: Executed TCs | P3: =SUM(Q3:R3) -> 157 | Q3: =SUM(Q4:Q5) -> 139 | R3: =SUM(R4:R5) -> 18 | S3: Executed TCs | T3: =SUM(U3:V3) -> 157 | U3: =SUM(U4:U5) -> 139 | V3: =SUM(V4:V5) -> 18 | W3: Executed TCs | X3: =SUM(Y3:Z3) -> 0 | Y3: =SUM(Y4:Y5) -> 0 | Z3: =SUM(Z4:Z5) -> 0 | AA3: Executed TCs | AB3: =SUM(AC3:AD3) -> 0 | AC3: =SUM(AC4:AC5) -> 0 | AD3: =SUM(AD4:AD5) -> 0 | AE3: Executed TCs | AF3: =SUM(AG3:AH3) -> 0 | AG3: =SUM(AG4:AG5) -> 0 | AH3: =SUM(AH4:AH5) -> 0 | AI3: =SUMIFS($AI$15:$AI$1500,$L$15:$L$1500,"*Manual*", INDIRECT(VLOOKUP($AN$2,$AM$3:$AN$7,2,FALSE)),"*"&AJ3&"*") -> 0 | AJ3: Tuan | AK3: =COUNTIFS($L$15:$L$1500, "*Manual*", INDIRECT(VLOOKUP($AN$2,$AM$3:$AN$7,2,FALSE)), "*"&AJ3&"*") -> 0 | AM3: 1 | AN3: $Q$15:$Q$1500 | AO3: =SUMIFS($AI$15:$AI$1500,$L$15:$L$1500,"*Manual*", INDIRECT(AN3),"<>"&"") -> 115 | AP3: =COUNTIFS($L$15:$L$1500,"*Manual*",INDIRECT(AN3),"<>"&"") -> 18 | AQ3: =IFERROR(AO3/AP3,0) -> 6.3888889 | AR3: =IF(AQ3>0,IF(AQ3>=14,"D",IF(AQ3>=8,"N","E")),"NOT-YET") -> E
H4: D | I4: =COUNTIFS($L$15:$L$1500,"*Manual*",INDIRECT(VLOOKUP($AN$2,$AM$3:$AN$7,2,FALSE)), "<>"&"", $AI$15:$AI$1500,"*"&H4&"*") -> 0 | J4: =SUMIFS($AI$15:$AI$1500,$L$15:$L$1500,"*Manual*", INDIRECT(VLOOKUP($AN$2,$AM$3:$AN$7,2,FALSE)),"<>"&"",$AJ$15:$AJ$1500,"*"&H4&"*") -> 60 | M4: GCS | N4: =COUNTIFS($N$15:$N$1000,"*GCS*") -> 157 | O4: Pass | P4: =COUNTIF(O$15:O$1000,O4) -> 152 | Q4: =SUM(COUNTIFS(Q$15:Q$2500,{"*Ju*","*RCP*"},O$15:O$2500,O4)) -> 135 | R4: =P4-Q4 -> 17 | S4: Pass | T4: =COUNTIF(S$15:S$1000,S4) -> 153 | U4: =SUM(COUNTIFS(U$15:U$2500,{"*Ju*","*RCP*"},S$15:S$2500,S4)) -> 135 | V4: =T4-U4 -> 18 | W4: Pass | X4: =COUNTIF(W$15:W$1000,W4) -> 0 | Y4: =SUM(COUNTIFS(Y$15:Y$2500,{"*Ju*","*RCP*"},W$15:W$2500,W4)) -> 0 | Z4: =X4-Y4 -> 0 | AA4: Pass | AB4: =COUNTIF(AA$15:AA$1000,AA4) -> 0 | AC4: =SUM(COUNTIFS(AC$15:AC$2500,{"*Ju*","*RCP*"},AA$15:AA$2500,AA4)) -> 0 | AD4: =AB4-AC4 -> 0 | AE4: Pass | AF4: =COUNTIF(AE$15:AE$1000,AE4) -> 0 | AG4: =SUM(COUNTIFS(AG$15:AG$2500,{"*Ju*","*RCP*"},AE$15:AE$2500,AE4)) -> 0 | AH4: =AF4-AG4 -> 0 | AI4: =SUMIFS($AI$15:$AI$1500,$L$15:$L$1500,"*Manual*", INDIRECT(VLOOKUP($AN$2,$AM$3:$AN$7,2,FALSE)),"*"&AJ4&"*") -> 0 | AJ4: Long | AK4: =COUNTIFS($L$15:$L$1500, "*Manual*", INDIRECT(VLOOKUP($AN$2,$AM$3:$AN$7,2,FALSE)), "*"&AJ4&"*") -> 0 | AM4: 2 | AN4: $U$15:$U$1500 | AO4: =SUMIFS($AI$15:$AI$1500,$L$15:$L$1500,"*Manual*", INDIRECT(AN4),"<>"&"") -> 115 | AP4: =COUNTIFS($L$15:$L$1500,"*Manual*",INDIRECT(AN4),"<>"&"") -> 18 | AQ4: =IFERROR(AO4/AP4,0) -> 6.3888889 | AR4: =IF(AQ4>0,IF(AQ4>=14,"D",IF(AQ4>=8,"N","E")),"NOT-YET") -> E
H5: N | I5: =COUNTIFS($L$15:$L$1500,"*Manual*",INDIRECT(VLOOKUP($AN$2,$AM$3:$AN$7,2,FALSE)), "<>"&"", $AI$15:$AI$1500,"*"&H5&"*") -> 0 | J5: =SUMIFS($AI$15:$AI$1500,$L$15:$L$1500,"*Manual*", INDIRECT(VLOOKUP($AN$2,$AM$3:$AN$7,2,FALSE)),"<>"&"",$AJ$15:$AJ$1500,"*"&H5&"*") -> 10 | M5: Pass | N5: =COUNTIFS($M$15:$M$1000,"*Pass*") -> 153 | O5: Fail | P5: =SUM(P6:P9) -> 5 | Q5: =SUM(Q6:Q9) -> 4 | R5: =SUM(R6:R9) -> 1 | S5: Fail | T5: =SUM(T6:T9) -> 4 | U5: =SUM(U6:U9) -> 4 | V5: =SUM(V6:V9) -> 0 | W5: Fail | X5: =SUM(X6:X9) -> 0 | Y5: =SUM(Y6:Y9) -> 0 | Z5: =SUM(Z6:Z9) -> 0 | AA5: Fail | AB5: =SUM(AB6:AB9) -> 0 | AC5: =SUM(AC6:AC9) -> 0 | AD5: =SUM(AD6:AD9) -> 0 | AE5: Fail | AF5: =SUM(AF6:AF9) -> 0 | AG5: =SUM(AG6:AG9) -> 0 | AH5: =SUM(AH6:AH9) -> 0 | AI5: =SUMIFS($AI$15:$AI$1500,$L$15:$L$1500,"*Manual*", INDIRECT(VLOOKUP($AN$2,$AM$3:$AN$7,2,FALSE)),"*"&AJ5&"*") -> 22 | AJ5: Linh | AK5: =COUNTIFS($L$15:$L$1500, "*Manual*", INDIRECT(VLOOKUP($AN$2,$AM$3:$AN$7,2,FALSE)), "*"&AJ5&"*") -> 2 | AM5: 3 | AN5: $Y$15:$Y$1500 | AO5: =SUMIFS($AI$15:$AI$1500,$L$15:$L$1500,"*Manual*", INDIRECT(AN5),"<>"&"") -> 0 | AP5: =COUNTIFS($L$15:$L$1500,"*Manual*",INDIRECT(AN5),"<>"&"") -> 0 | AQ5: =IFERROR(AO5/AP5,0) -> 0 | AR5: =IF(AQ5>0,IF(AQ5>=14,"D",IF(AQ5>=8,"N","E")),"NOT-YET") -> NOT-YET
A6: New in 5.3 RT | C6: =COUNTIF($K$15:$K$1000,"5.3") -> 0 | H6: E | I6: =COUNTIFS($L$15:$L$1500,"*Manual*",INDIRECT(VLOOKUP($AN$2,$AM$3:$AN$7,2,FALSE)), "<>"&"", $AI$15:$AI$1500,"*"&H6&"*") -> 0 | J6: =SUMIFS($AI$15:$AI$1500,$L$15:$L$1500,"*Manual*", INDIRECT(VLOOKUP($AN$2,$AM$3:$AN$7,2,FALSE)),"<>"&"",$AJ$15:$AJ$1500,"*"&H6&"*") -> 45 | M6: Fail | N6: =COUNTIFS($M$15:$M$1000,"*Fail*") -> 4 | O6: Fail (New) | P6: =COUNTIF(O$15:O$1000,"*"&O6&"*") -> 0 | Q6: =SUM(COUNTIFS(Q$15:Q$2500,{"*Ju*","*RCP*"},O$15:O$2500,O6)) -> 0 | R6: =P6-Q6 -> 0 | S6: Fail (New) | T6: =COUNTIF(S$15:S$1000,"*"&S6&"*") -> 0 | U6: =SUM(COUNTIFS(U$15:U$2500,{"*Ju*","*RCP*"},S$15:S$2500,S6)) -> 0 | V6: =T6-U6 -> 0 | W6: Fail (New) | X6: =COUNTIF(W$15:W$1000,"*"&W6&"*") -> 0 | Y6: =SUM(COUNTIFS(Y$15:Y$2500,{"*Ju*","*RCP*"},W$15:W$2500,W6)) -> 0 | Z6: =X6-Y6 -> 0 | AA6: Fail (New) | AB6: =COUNTIF(AA$15:AA$1000,"*"&AA6&"*") -> 0 | AC6: =SUM(COUNTIFS(AC$15:AC$2500,{"*Ju*","*RCP*"},AA$15:AA$2500,AA6)) -> 0 | AD6: =AB6-AC6 -> 0 | AE6: Fail (New) | AF6: =COUNTIF(AE$15:AE$1000,"*"&AE6&"*") -> 0 | AG6: =SUM(COUNTIFS(AG$15:AG$2500,{"*Ju*","*RCP*"},AE$15:AE$2500,AE6)) -> 0 | AH6: =AF6-AG6 -> 0 | AI6: =SUMIFS($AI$15:$AI$1500,$L$15:$L$1500,"*Manual*", INDIRECT(VLOOKUP($AN$2,$AM$3:$AN$7,2,FALSE)),"*"&AJ6&"*") -> 93 | AJ6: Muoi | AK6: =COUNTIFS($L$15:$L$1500, "*Manual*", INDIRECT(VLOOKUP($AN$2,$AM$3:$AN$7,2,FALSE)), "*"&AJ6&"*") -> 16 | AM6: 4 | AN6: $AC$15:$AC$1500 | AO6: =SUMIFS($AI$15:$AI$1500,$L$15:$L$1500,"*Manual*", INDIRECT(AN6),"<>"&"") -> 0 | AP6: =COUNTIFS($L$15:$L$1500,"*Manual*",INDIRECT(AN6),"<>"&"") -> 0 | AQ6: =IFERROR(AO6/AP6,0) -> 0 | AR6: =IF(AQ6>0,IF(AQ6>=14,"D",IF(AQ6>=8,"N","E")),"NOT-YET") -> NOT-YET
M7: Skip | N7: =COUNTIFS($M$15:$M$1000,"*Skip*") -> 0 | O7: Fail (Existing) | P7: =COUNTIF(O$15:O$1000,"*"&O7&"*") -> 0 | Q7: =SUM(COUNTIFS(Q$15:Q$2500,{"*Ju*","*RCP*"},O$15:O$2500,O7)) -> 0 | R7: =P7-Q7 -> 0 | S7: Fail (Existing) | T7: =COUNTIF(S$15:S$1000,"*"&S7&"*") -> 0 | U7: =SUM(COUNTIFS(U$15:U$2500,{"*Ju*","*RCP*"},S$15:S$2500,S7)) -> 0 | V7: =T7-U7 -> 0 | W7: Fail (Existing) | X7: =COUNTIF(W$15:W$1000,"*"&W7&"*") -> 0 | Y7: =SUM(COUNTIFS(Y$15:Y$2500,{"*Ju*","*RCP*"},W$15:W$2500,W7)) -> 0 | Z7: =X7-Y7 -> 0 | AA7: Fail (Existing) | AB7: =COUNTIF(AA$15:AA$1000,"*"&AA7&"*") -> 0 | AC7: =SUM(COUNTIFS(AC$15:AC$2500,{"*Ju*","*RCP*"},AA$15:AA$2500,AA7)) -> 0 | AD7: =AB7-AC7 -> 0 | AE7: Fail (Existing) | AF7: =COUNTIF(AE$15:AE$1000,"*"&AE7&"*") -> 0 | AG7: =SUM(COUNTIFS(AG$15:AG$2500,{"*Ju*","*RCP*"},AE$15:AE$2500,AE7)) -> 0 | AH7: =AF7-AG7 -> 0 | AI7: =SUMIFS($AI$15:$AI$1500,$L$15:$L$1500,"*Manual*", INDIRECT(VLOOKUP($AN$2,$AM$3:$AN$7,2,FALSE)),"*"&AJ7&"*") -> 0 | AJ7: Thinh | AK7: =COUNTIFS($L$15:$L$1500, "*Manual*", INDIRECT(VLOOKUP($AN$2,$AM$3:$AN$7,2,FALSE)), "*"&AJ7&"*") -> 0 | AM7: 5 | AN7: $AG$15:$AG$1500 | AO7: =SUMIFS($AI$15:$AI$1500,$L$15:$L$1500,"*Manual*", INDIRECT(AN7),"<>"&"") -> 0 | AP7: =COUNTIFS($L$15:$L$1500,"*Manual*",INDIRECT(AN7),"<>"&"") -> 0 | AQ7: =IFERROR(AO7/AP7,0) -> 0 | AR7: =IF(AQ7>0,IF(AQ7>=14,"D",IF(AQ7>=8,"N","E")),"NOT-YET") -> NOT-YET
H8: Number of TC that has time bigger than 60 minutes | I8: =COUNTIFS($L$15:$L$1500,"*Manual*",INDIRECT(VLOOKUP($AN$2,$AM$3:$AN$7,2,FALSE)), "<>"&"", $AI$15:$AI$1500,">=60") -> 0 | J8: =SUMIFS($AI$15:$AI$1500,$L$15:$L$1500,"*Manual*", INDIRECT(VLOOKUP($AN$2,$AM$3:$AN$7,2,FALSE)),"<>"&"",$AI$15:$AI$1500,">=60") -> 0 | O8: Fail (Degrade) | P8: =COUNTIF(O$15:O$1000,"*"&O8&"*") -> 0 | Q8: =SUM(COUNTIFS(Q$15:Q$2500,{"*Ju*","*RCP*"},O$15:O$2500,O8)) -> 0 | R8: =P8-Q8 -> 0 | S8: Fail (Degrade) | T8: =COUNTIF(S$15:S$1000,"*"&S8&"*") -> 0 | U8: =SUM(COUNTIFS(U$15:U$2500,{"*Ju*","*RCP*"},S$15:S$2500,S8)) -> 0 | V8: =T8-U8 -> 0 | W8: Fail (Degrade) | X8: =COUNTIF(W$15:W$1000,"*"&W8&"*") -> 0 | Y8: =SUM(COUNTIFS(Y$15:Y$2500,{"*Ju*","*RCP*"},W$15:W$2500,W8)) -> 0 | Z8: =X8-Y8 -> 0 | AA8: Fail (Degrade) | AB8: =COUNTIF(AA$15:AA$1000,"*"&AA8&"*") -> 0 | AC8: =SUM(COUNTIFS(AC$15:AC$2500,{"*Ju*","*RCP*"},AA$15:AA$2500,AA8)) -> 0 | AD8: =AB8-AC8 -> 0 | AE8: Fail (Degrade) | AF8: =COUNTIF(AE$15:AE$1000,"*"&AE8&"*") -> 0 | AG8: =SUM(COUNTIFS(AG$15:AG$2500,{"*Ju*","*RCP*"},AE$15:AE$2500,AE8)) -> 0 | AH8: =AF8-AG8 -> 0 | AI8: =SUMIFS($AI$15:$AI$1500,$L$15:$L$1500,"*Manual*", INDIRECT(VLOOKUP($AN$2,$AM$3:$AN$7,2,FALSE)),"*"&AJ8&"*") -> 0 | AJ8: Quang | AK8: =COUNTIFS($L$15:$L$1500, "*Manual*", INDIRECT(VLOOKUP($AN$2,$AM$3:$AN$7,2,FALSE)), "*"&AJ8&"*") -> 0
O9: Fail (Known) | P9: =COUNTIF(O$15:O$1000,"*"&O9&"*") -> 5 | Q9: =SUM(COUNTIFS(Q$15:Q$2500,{"*Ju*","*RCP*"},O$15:O$2500,O9)) -> 4 | R9: =P9-Q9 -> 1 | S9: Fail (Known) | T9: =COUNTIF(S$15:S$1000,"*"&S9&"*") -> 4 | U9: =SUM(COUNTIFS(U$15:U$2500,{"*Ju*","*RCP*"},S$15:S$2500,S9)) -> 4 | V9: =T9-U9 -> 0 | W9: Fail (Known) | X9: =COUNTIF(W$15:W$1000,"*"&W9&"*") -> 0 | Y9: =SUM(COUNTIFS(Y$15:Y$2500,{"*Ju*","*RCP*"},W$15:W$2500,W9)) -> 0 | Z9: =X9-Y9 -> 0 | AA9: Fail (Known) | AB9: =COUNTIF(AA$15:AA$1000,"*"&AA9&"*") -> 0 | AC9: =SUM(COUNTIFS(AC$15:AC$2500,{"*Ju*","*RCP*"},AA$15:AA$2500,AA9)) -> 0 | AD9: =AB9-AC9 -> 0 | AE9: Fail (Known) | AF9: =COUNTIF(AE$15:AE$1000,"*"&AE9&"*") -> 0 | AG9: =SUM(COUNTIFS(AG$15:AG$2500,{"*Ju*","*RCP*"},AE$15:AE$2500,AE9)) -> 0 | AH9: =AF9-AG9 -> 0 | AI9: =SUMIFS($AI$15:$AI$1500,$L$15:$L$1500,"*Manual*", INDIRECT(VLOOKUP($AN$2,$AM$3:$AN$7,2,FALSE)),"*"&AJ9&"*") -> 0 | AJ9: Anh | AK9: =COUNTIFS($L$15:$L$1500, "*Manual*", INDIRECT(VLOOKUP($AN$2,$AM$3:$AN$7,2,FALSE)), "*"&AJ9&"*") -> 0
O10: Skip | P10: =COUNTIF(O$15:O$1000,"*"&O10&"*") -> 0 | Q10: =SUM(COUNTIFS(Q$15:Q$2500,{"*Ju*","*RCP*"},O$15:O$2500,O10)) -> 0 | R10: =P10-Q10 -> 0 | S10: Skip | T10: =COUNTIF(S$15:S$1000,"*"&S10&"*") -> 0 | U10: =SUM(COUNTIFS(U$15:U$2500,{"*Ju*","*RCP*"},S$15:S$2500,S10)) -> 0 | V10: =T10-U10 -> 0 | W10: Skip | X10: =COUNTIF(W$15:W$1000,"*"&W10&"*") -> 0 | Y10: =SUM(COUNTIFS(Y$15:Y$2500,{"*Ju*","*RCP*"},W$15:W$2500,W10)) -> 0 | Z10: =X10-Y10 -> 0 | AA10: Skip | AB10: =COUNTIF(AA$15:AA$1000,"*"&AA10&"*") -> 0 | AC10: =SUM(COUNTIFS(AC$15:AC$2500,{"*Ju*","*RCP*"},AA$15:AA$2500,AA10)) -> 0 | AD10: =AB10-AC10 -> 0 | AE10: Skip | AF10: =COUNTIF(AE$15:AE$1000,"*"&AE10&"*") -> 0 | AG10: =SUM(COUNTIFS(AG$15:AG$2500,{"*Ju*","*RCP*"},AE$15:AE$2500,AE10)) -> 0 | AH10: =AF10-AG10 -> 0 | AI10: =SUM(AI3:AI9) -> 115 | AJ10: =IFERROR($AG$10/$AI$10,0) -> 0 | AK10: =SUM(AK3:AK9) -> 18
O11: 1 | S11: 2 | W11: 3 | AA11: 4 | AE11: 5 | AI11: Actual | AM11: GCS/Plan
O12: =Summary!R4 -> e2studio_v5.4.0.001-Part1 | S12: =Summary!AM4 -> e2studio_v5.4.0.005 | W12: =Summary!BH4 -> TBD | AA12: =Summary!CC4 -> TBD | AE12: =Summary!CX4 -> TBD | AI12: =SUM(AI15:AI1500) -> 115 | AJ12: =IF($AJ$10>0,IF($AJ$10>=14,"D",IF($AJ$10>=8,"N","E")),"NOT-YET") -> NOT-YET | AM12: =SUM($AM$15:$AM$1500) -> 241 | AN12: =IF(AM12>0,IF($AN$14>=14,"D",IF($AN$14>=8,"N","E")),"NOT-YET") -> N
B13: ID | C13: Test items | D13: Test cases | E13: Expected result | F13: Device- Debugger- Compiler | G13: RCPTT memo (RSD only) | I13: PCL notes | J13: PCL creator | K13: Added to RT of e2s version | L13: Auto | M13: Result on e2 studio v5.3, SSP_1.2.0-b.1 | O13: Result | P13: Date | Q13: Tester | R13: Remark | S13: Result | T13: Date | U13: Tester | V13: Remark | W13: Result | X13: Date | Y13: Tester | Z13: Remark | AA13: Result | AB13: Date | AC13: Tester | AD13: Remark | AE13: Result | AF13: Date | AG13: Tester | AH13: Remark | AI13: Time to execute manual (minute) | AJ13: Level of manual TC | AM13: Time to execute manual (minute) | AN13: Level of manual TC
G14: test phase | H14: status to be replaced | M14: Result | N14: PIC | AM14: Everage time per TC | AN14: =IFERROR($AM$12/COUNTIF($AM$15:$AM$1500, ">0"),0) -> 13.388889
B15: 1-1-11> Building resources | L15: - | AN15: =IF(AM15>0, IF(AM15>=14,"D",IF(AM15>=8,"N","E")),"")
B16: 1-1-11-1-001 | C16: > Performing builds automatically | D16: 1. Window > Preferences > General > Workspace 2. Check ON [Build automatically] check-box 3. Click OK | E16: Perform builds automatically whenever create new project / import project | F16: Simulator | G16: FR | H16: not yet | I16: Select [Build on resource save(Auto bulid)] in Project Properties> C/C++ Build >Behaviour | J16: RVC GCSTrangT | K16: 5.1 and older | L16: Ju147_RT410 | M16: Pass | N16: GCS/Ju147 | O16: Pass | P16: 42776 | Q16: GCS/LinhD[/Ju/147] | S16: Pass | T16: 42794 | U16: GCS/LinhD[/Ju/147] | AJ16: =IF(AI16>0, IF(AI16>=14,"D",IF(AI16>=8,"N","E")),"") | AN16: =IF(AM16>0, IF(AM16>=14,"D",IF(AM16>=8,"N","E")),"")
B17: 1-1-11-2-001 | C17: > Performing builds manually | D17: <Build action – Build> 1. Create 2 project C with RX tool chain 2. [Project] menu > Build All | E17: _ 2 project are build successful with only build configuration active | F17: Simulator | G17: SR | H17: done | J17: RVC GCSTrangT | K17: 5.1 and older | L17: Ju147_RT410 | M17: Pass | N17: GCS/Ju147 | O17: Pass | P17: 42776 | Q17: GCS/LinhD[/Ju/147] | S17: Pass | T17: 42794 | U17: GCS/LinhD[/Ju/147] | AJ17: =IF(AI17>0, IF(AI17>=14,"D",IF(AI17>=8,"N","E")),"") | AN17: =IF(AM17>0, IF(AM17>=14,"D",IF(AM17>=8,"N","E")),"")
B18: 1-1-11-2-002 | D18: <Build action – Build> 1. Create 2 project C with RX tool chain 2. Select project and right click 3. Pop-up (Project item on project tree) > Build Configurations > Build All | E18: All build configuration are build successful for the project selected. | F18: Simulator | G18: SR | H18: done | J18: RVC GCSTrangT | K18: 5.1 and older | L18: Ju147_RT410 | M18: Pass | N18: GCS/Ju147 | O18: Pass | P18: 42776 | Q18: GCS/LinhD[/Ju/147] | S18: Pass | T18: 42794 | U18: GCS/LinhD[/Ju/147] | AJ18: =IF(AI18>0, IF(AI18>=14,"D",IF(AI18>=8,"N","E")),"") | AN18: =IF(AM18>0, IF(AM18>=14,"D",IF(AM18>=8,"N","E")),"")
B19: 1-1-11-2-003 | D19: <Build action – Build> 1. Create 2 project C with RX tool chain 2. Ctrl+B (Build All) | E19: _ 2 project are build successful with only build configuration active | F19: Simulator | G19: SR | H19: done | J19: RVC GCSTrangT | K19: 5.1 and older | L19: Ju147_RT410 | M19: Pass | N19: GCS/Ju147 | O19: Pass | P19: 42776 | Q19: GCS/LinhD[/Ju/147] | S19: Pass | T19: 42794 | U19: GCS/LinhD[/Ju/147] | AJ19: =IF(AI19>0, IF(AI19>=14,"D",IF(AI19>=8,"N","E")),"") | AN19: =IF(AM19>0, IF(AM19>=14,"D",IF(AM19>=8,"N","E")),"")
B20: 1-1-11-2-004 | D20: <Build action – Build> 1. Create C project with RX 2. Select project and right click 3. Pop-up (Project item on project tree) > Build Configurations > Build Selected… 4. Click OK button | E20: 3. Open Clean and Rebuild Configurations dialog _Display all build configuation of project (Debug, HardwaredDebug, Release, CustomDebug, HewDebug) _ Auto checked to Active build _ Clean selected configurations checkbox is checked _ Build selected confugurations checkbox is checked 4. Build successful | F20: Simulator | G20: SR | H20: done | J20: RVC GCSTrangT | K20: 5.1 and older | L20: Ju147_RT410 | M20: Pass | N20: GCS/Ju147 | O20: Pass | P20: 42776 | Q20: GCS/LinhD[/Ju/147] | S20: Pass | T20: 42794 | U20: GCS/LinhD[/Ju/147] | AJ20: =IF(AI20>0, IF(AI20>=14,"D",IF(AI20>=8,"N","E")),"") | AN20: =IF(AM20>0, IF(AM20>=14,"D",IF(AM20>=8,"N","E")),"")
B21: 1-1-11-2-005 | D21: <Build action – Build> 1. Create C project with RX 2. Select project and [Project] menu > Build Project | E21: Selected project is build successful | F21: Simulator | G21: SR | H21: done | J21: RVC GCSTrangT | K21: 5.1 and older | L21: Ju147_RT410 | M21: Pass | N21: GCS/Ju147 | O21: Pass | P21: 42776 | Q21: GCS/LinhD[/Ju/147] | S21: Pass | T21: 42794 | U21: GCS/LinhD[/Ju/147] | AJ21: =IF(AI21>0, IF(AI21>=14,"D",IF(AI21>=8,"N","E")),"") | AN21: =IF(AM21>0, IF(AM21>=14,"D",IF(AM21>=8,"N","E")),"")
B22: 1-1-11-2-006 | D22: <Build action – Build> 1. Create C project with RX 2. Select project and Pop-up (Project item on project tree) > Build Project | E22: Selected project is build successful | F22: Simulator | G22: SR | H22: done | J22: RVC GCSTrangT | K22: 5.1 and older | L22: Ju147_RT410 | M22: Pass | N22: GCS/Ju147 | O22: Pass | P22: 42776 | Q22: GCS/LinhD[/Ju/147] | S22: Pass | T22: 42794 | U22: GCS/LinhD[/Ju/147] | AJ22: =IF(AI22>0, IF(AI22>=14,"D",IF(AI22>=8,"N","E")),"") | AN22: =IF(AM22>0, IF(AM22>=14,"D",IF(AM22>=8,"N","E")),"")
B23: 1-1-11-2-007 | D23: <Build action – Build> 1. Create C project with RX 2. Select project and Select Build Project on Toolbar button | E23: Selected project is build successful | F23: Simulator | G23: SR | H23: done | J23: RVC GCSTrangT | K23: 5.1 and older | L23: Ju147_RT410 | M23: Pass | N23: GCS/Ju147 | O23: Pass | P23: 42776 | Q23: GCS/LinhD[/Ju/147] | S23: Pass | T23: 42794 | U23: GCS/LinhD[/Ju/147] | AJ23: =IF(AI23>0, IF(AI23>=14,"D",IF(AI23>=8,"N","E")),"") | AN23: =IF(AM23>0, IF(AM23>=14,"D",IF(AM23>=8,"N","E")),"")
B24: 1-1-11-2-008 | D24: <Build action – Clean> *Pre-Condition: - Start build automatically is off - Start a build immediately > Build the entire workspace is checked - Create C project with RX and build project 1. [Project] menu > Clean... > Clean all projects > Start a build immediately > Build the entire workspace 2. Select project > Right click > Pop-up (Project item on project tree) > Build Configurations > Clean All | E24: _ Clean project (Output files are deleted) _ Project are build successful | F24: Simulator | G24: FR | H24: not yet | I24: Should be tested with multiple project] Trac #4152 | J24: RVC GCSTrangT | K24: 5.1 and older | L24: Ju147_RT410 | M24: Pass | N24: GCS/Ju147 | O24: Pass | P24: 42776 | Q24: GCS/LinhD[/Ju/147] | S24: Pass | T24: 42794 | U24: GCS/LinhD[/Ju/147] | AJ24: =IF(AI24>0, IF(AI24>=14,"D",IF(AI24>=8,"N","E")),"") | AN24: =IF(AM24>0, IF(AM24>=14,"D",IF(AM24>=8,"N","E")),"")
B25: 1-1-11-2-009 | D25: <Build action – Clean> *Pre-Condition: - Start build automatically is off - Start a build immediately > Build the entire workspace is checked - Create 2 C project with RX 1. [Project] menu > Clean... > Clean all projects > Start a build immediately > Build the entire workspace 2. [Project] menu > Clean... > Clean all projects | E25: _ Clean project (Output files are deleted) _ 2 project are build successful with only build configuration active | F25: Simulator | G25: FR | H25: not yet | I25: Should be tested with multiple project] Trac #4140 | J25: RVC GCSTrangT | K25: 5.1 and older | L25: Ju147_RT410 | M25: Pass | N25: GCS/Ju147 | O25: Pass | P25: 42776 | Q25: GCS/LinhD[/Ju/147] | S25: Pass | T25: 42794 | U25: GCS/LinhD[/Ju/147] | AJ25: =IF(AI25>0, IF(AI25>=14,"D",IF(AI25>=8,"N","E")),"") | AN25: =IF(AM25>0, IF(AM25>=14,"D",IF(AM25>=8,"N","E")),"")
B26: 1-1-11-2-010 | D26: <Build action – Clean> *Pre-Condition: - Start build automatically is off - Start a build immediately > Build the entire workspace is checked - Create 2 C project with RX and build project 1. [Project] menu > Clean... > Clean all projects > Start a build immediately > Build only the selected projects 2. Select project > Right click > Pop-up (Project item on project tree) > Build Configurations > Clean All | E26: _ Clean project (Output files are deleted) _ Project selected are build successful | F26: Simulator | G26: FR | H26: not yet | J26: RVC GCSTrangT | K26: 5.1 and older | L26: Ju147_RT410 | M26: Pass | N26: GCS/Ju147 | O26: Pass | P26: 42776 | Q26: GCS/LinhD[/Ju/147] | S26: Pass | T26: 42794 | U26: GCS/LinhD[/Ju/147] | AJ26: =IF(AI26>0, IF(AI26>=14,"D",IF(AI26>=8,"N","E")),"") | AN26: =IF(AM26>0, IF(AM26>=14,"D",IF(AM26>=8,"N","E")),"")
B27: 1-1-11-2-011 | D27: <Build action – Clean> *Pre-Condition: - Start build automatically is off - Start a build immediately > Build the entire workspace is checked - Create 2 C project with RX and build project 1. [Project] menu > Clean... > Clean all projects > Start a build immediately > Build only the selected projects 2. [Project] menu > Clean... > Clean all projects | E27: _ Clean project (Output files are deleted) _ Project selected are build successful | F27: Simulator | G27: FR | H27: not yet | J27: RVC GCSTrangT | K27: 5.1 and older | L27: Ju147_RT410 | M27: Pass | N27: GCS/Ju147 | O27: Pass | P27: 42776 | Q27: GCS/LinhD[/Ju/147] | S27: Pass | T27: 42794 | U27: GCS/LinhD[/Ju/147] | AJ27: =IF(AI27>0, IF(AI27>=14,"D",IF(AI27>=8,"N","E")),"") | AN27: =IF(AM27>0, IF(AM27>=14,"D",IF(AM27>=8,"N","E")),"")
B28: 1-1-11-2-012 | D28: <Build action – Clean> *Pre-Condition: - Start build automatically is off - Start a build immediately > Build the entire workspace is checked - Create 2 C project with RX and build project 1. [Project] menu > Clean... > Clean projects selected below 2. Pop-up (Project item on project tree) > Build Configurations > Clean All | E28: Clean project (Output files are deleted) Build NOT occurs | F28: Simulator | G28: FR | H28: not yet | J28: RVC GCSTrangT | K28: 5.1 and older | L28: Ju147_RT410 | M28: Pass | N28: GCS/Ju147 | O28: Pass | P28: 42776 | Q28: GCS/LinhD[/Ju/147] | S28: Pass | T28: 42794 | U28: GCS/LinhD[/Ju/147] | AJ28: =IF(AI28>0, IF(AI28>=14,"D",IF(AI28>=8,"N","E")),"") | AN28: =IF(AM28>0, IF(AM28>=14,"D",IF(AM28>=8,"N","E")),"")
B29: 1-1-11-2-013 | D29: <Build action – Clean> *Pre-Condition: - Start build automatically is off - Start a build immediately > Build the entire workspace is checked - Create 2 C project with RX and build project 1. [Project] menu > Clean... > Clean projects selected below 2. [Project] menu > Clean... > Clean all projects | E29: Clean project (Output files are deleted) Build NOT occurs | F29: Simulator | G29: FR | H29: not yet | J29: RVC GCSTrangT | K29: 5.1 and older | L29: Ju147_RT410 | M29: Pass | N29: GCS/Ju147 | O29: Pass | P29: 42776 | Q29: GCS/LinhD[/Ju/147] | S29: Pass | T29: 42794 | U29: GCS/LinhD[/Ju/147] | AJ29: =IF(AI29>0, IF(AI29>=14,"D",IF(AI29>=8,"N","E")),"") | AN29: =IF(AM29>0, IF(AM29>=14,"D",IF(AM29>=8,"N","E")),"")
B30: 1-1-11-2-014 | D30: <Build action – Clean> *Pre-Condition: - Start build automatically is off - Start a build immediately > Build the entire workspace is checked - Create 2 C project with RX and build project 1. [Project] menu > Clean... > Clean projects selected below > Start a build immediately > Build the entire workspace 2. Pop-up (Project item on project tree) > Build Configurations > Clean All | E30: Clean project (Output files are deleted) Build occurs | F30: Simulator | G30: FR | H30: not yet | J30: RVC GCSTrangT | K30: 5.1 and older | L30: Ju147_RT410 | M30: Pass | N30: GCS/Ju147 | O30: Pass | P30: 42776 | Q30: GCS/LinhD[/Ju/147] | S30: Pass | T30: 42794 | U30: GCS/LinhD[/Ju/147] | AJ30: =IF(AI30>0, IF(AI30>=14,"D",IF(AI30>=8,"N","E")),"") | AN30: =IF(AM30>0, IF(AM30>=14,"D",IF(AM30>=8,"N","E")),"")
B31: 1-1-11-2-015 | D31: <Build action – Clean> *Pre-Condition: - Start build automatically is off - Start a build immediately > Build the entire workspace is checked - Create 2 C project with RX and build project 1. [Project] menu > Clean... > Clean projects selected below > Start a build immediately > Build the entire workspace 2. [Project] menu > Clean... > Clean all projects | E31: Clean project (Output files are deleted) Build occurs | F31: Simulator | G31: FR | H31: not yet | J31: RVC GCSTrangT | K31: 5.1 and older | L31: Ju147_RT410 | M31: Pass | N31: GCS/Ju147 | O31: Pass | P31: 42776 | Q31: GCS/LinhD[/Ju/147] | S31: Pass | T31: 42794 | U31: GCS/LinhD[/Ju/147] | AJ31: =IF(AI31>0, IF(AI31>=14,"D",IF(AI31>=8,"N","E")),"") | AN31: =IF(AM31>0, IF(AM31>=14,"D",IF(AM31>=8,"N","E")),"")
B32: 1-1-11-2-016 | D32: <Build action – Clean> *Pre-Condition: - Start build automatically is off - Start a build immediately > Build the entire workspace is checked - Create 2 C project with RX and build project 1. [Project] menu > Clean... > Clean projects selected below > Start a build immediately > Build only the 2. Pop-up (Project item on project tree) > Build Configurations > Clean All | E32: Clean project (Output files are deleted) Build occurs | F32: Simulator | G32: FR | H32: not yet | J32: RVC GCSTrangT | K32: 5.1 and older | L32: Ju147_RT410 | M32: Pass | N32: GCS/Ju147 | O32: Pass | P32: 42776 | Q32: GCS/LinhD[/Ju/147] | S32: Pass | T32: 42794 | U32: GCS/LinhD[/Ju/147] | AJ32: =IF(AI32>0, IF(AI32>=14,"D",IF(AI32>=8,"N","E")),"") | AN32: =IF(AM32>0, IF(AM32>=14,"D",IF(AM32>=8,"N","E")),"")
B33: 1-1-11-2-017 | D33: <Build action – Clean> *Pre-Condition: - Start build automatically is off - Start a build immediately > Build the entire workspace is checked - Create 2 C project with RX and build project 1. [Project] menu > Clean... > Clean projects selected below > Start a build immediately > Build only the 2. [Project] menu > Clean... > Clean all projects | E33: Clean project (Output files are deleted) Build occurs | F33: Simulator | G33: FR | H33: not yet | J33: RVC GCSTrangT | K33: 5.1 and older | L33: Ju147_RT410 | M33: Pass | N33: GCS/Ju147 | O33: Pass | P33: 42776 | Q33: GCS/LinhD[/Ju/147] | S33: Pass | T33: 42794 | U33: GCS/LinhD[/Ju/147] | AJ33: =IF(AI33>0, IF(AI33>=14,"D",IF(AI33>=8,"N","E")),"") | AN33: =IF(AM33>0, IF(AM33>=14,"D",IF(AM33>=8,"N","E")),"")
